Workbook

Sheet DEC 2026
A1: 44895 | C1: RECETTE | G1: CAISSE | M1: MOUVEMENT CAISSE | P1: CAISSE MOIS PREC | Q1: PAYEMENT FOURNISSEUR CAISSE | R1: MONTANT | S1: TOTAL | T1: DATE SORTIE | Y1: FOURNISSEUR | Z1: DATE | AA1: REFERENCE | AB1: COMPTE | AC1: HTVA | AD1: TVA | AE1: MONTANT | AF1: PAIEMENT | AG1: CAISSE | AH1: DATE | AI1: ECHEANCE
A2: DATE | B2: FACTURE | C2: 6 | D2: 12 | E2: 21 | F2: TOTAL | G2: CHIFF | H2: carte | I2: cadeau0 | J2: bque | K2: liquide | L2: TOT CAIS | M2: SORTIE | N2: vers ban | O2: solde cai | P2: ='NOV 2026'!P33 -> 268.9 | AB2: 44895
A3: 44895 | F3: =SUM(B3:E3) -> 0 | G3: =F3 -> 0 | K3: =SUM(F3-H3-J3-I3) -> 0 | L3: =SUM(F3-H3-J3-I3) -> 0 | O3: =SUM(L3-M3-N3+P2) -> 268.9 | X3: 1 | AE3: =SUM(AC3:AD3) -> 0 | AJ3: 0
A4: 44896 | F4: =SUM(B4:E4) -> 0 | G4: =F4 -> 0 | K4: =SUM(F4-H4-J4-I4) -> 0 | L4: =SUM(F4-H4-J4-I4) -> 0 | O4: =SUM(L4-M4-N4+O3+P4) -> 268.9 | X4: 2 | AE4: =SUM(AC4:AD4) -> 0 | AJ4: =AE4 -> 0
A5: 44897 | F5: =SUM(B5:E5) -> 0 | G5: =F5 -> 0 | K5: =SUM(F5-H5-J5-I5) -> 0 | L5: =SUM(F5-H5-J5-I5) -> 0 | O5: =SUM(L5-M5-N5+O4+P5) -> 268.9 | X5: 3 | AE5: =SUM(AC5:AD5) -> 0 | AJ5: 0
A6: 44898 | F6: =SUM(B6:E6) -> 0 | G6: =F6 -> 0 | K6: =SUM(F6-H6-J6-I6) -> 0 | L6: =SUM(F6-H6-J6-I6) -> 0 | O6: =SUM(L6-M6-N6+O5+P6) -> 268.9 | X6: 4 | AE6: =SUM(AC6:AD6) -> 0 | AJ6: 0
A7: 44899 | F7: =SUM(B7:E7) -> 0 | G7: =F7 -> 0 | K7: =SUM(F7-H7-J7-I7) -> 0 | L7: =SUM(F7-H7-J7-I7) -> 0 | O7: =SUM(L7-M7-N7+O6+P7) -> 268.9 | X7: 5 | AE7: =SUM(AC7:AD7) -> 0 | AJ7: 0
A8: 44900 | F8: =SUM(B8:E8) -> 0 | G8: =F8 -> 0 | K8: =SUM(F8-H8-J8-I8) -> 0 | L8: =SUM(F8-H8-J8-I8) -> 0 | O8: =SUM(L8-M8-N8+O7+P8) -> 268.9 | X8: 6 | AE8: =SUM(AC8:AD8) -> 0 | AJ8: 0
A9: 44901 | F9: =SUM(B9:E9) -> 0 | G9: =F9 -> 0 | K9: =SUM(F9-H9-J9-I9) -> 0 | L9: =SUM(F9-H9-J9-I9) -> 0 | O9: =SUM(L9-M9-N9+O8) -> 268.9 | X9: 7 | AE9: =SUM(AC9:AD9) -> 0 | AJ9: =AE9 -> 0
A10: 44902 | F10: =SUM(B10:E10) -> 0 | G10: =F10 -> 0 | K10: =SUM(F10-H10-J10-I10) -> 0 | L10: =SUM(F10-H10-J10-I10) -> 0 | O10: =SUM(L10-M10-N10+O9) -> 268.9 | X10: 8 | AE10: =SUM(AC10:AD10) -> 0 | AJ10: =AE10 -> 0
A11: 44903 | F11: =SUM(B11:E11) -> 0 | G11: =F11 -> 0 | K11: =SUM(F11-H11-J11-I11) -> 0 | L11: =SUM(F11-H11-J11-I11) -> 0 | O11: =SUM(L11-M11-N11+O10) -> 268.9 | X11: 9 | AE11: =SUM(AC11:AD11) -> 0 | AJ11: =AE11 -> 0
A12: 44904 | F12: =SUM(B12:E12) -> 0 | G12: =F12 -> 0 | K12: =SUM(F12-H12-J12-I12) -> 0 | L12: =SUM(F12-H12-J12-I12) -> 0 | O12: =SUM(L12-M12-N12+O11) -> 268.9 | X12: 10 | AE12: =SUM(AC12:AD12) -> 0 | AJ12: =AE12 -> 0
A13: 44905 | F13: =SUM(B13:E13) -> 0 | G13: =F13 -> 0 | K13: =SUM(F13-H13-J13-I13) -> 0 | L13: =SUM(F13-H13-J13-I13) -> 0 | O13: =SUM(L13-M13-N13+O12) -> 268.9 | X13: 11 | AE13: =SUM(AC13:AD13) -> 0 | AJ13: =AE13 -> 0
A14: 44906 | F14: =SUM(B14:E14) -> 0 | G14: =F14 -> 0 | K14: =SUM(F14-H14-J14-I14) -> 0 | L14: =SUM(F14-H14-J14-I14) -> 0 | O14: =SUM(L14-M14-N14+O13) -> 268.9 | X14: 12 | AE14: =SUM(AC14:AD14) -> 0 | AJ14: =AE14 -> 0
A15: 44907 | F15: =SUM(B15:E15) -> 0 | G15: =F15 -> 0 | K15: =SUM(F15-H15-J15-I15) -> 0 | L15: =SUM(F15-H15-J15-I15) -> 0 | O15: =SUM(L15-M15-N15+O14) -> 268.9 | X15: 13 | AE15: =SUM(AC15:AD15) -> 0 | AJ15: =AE15 -> 0
A16: 44908 | F16: =SUM(B16:E16) -> 0 | G16: =F16 -> 0 | K16: =SUM(F16-H16-J16-I16) -> 0 | L16: =SUM(F16-H16-J16-I16) -> 0 | O16: =SUM(L16-M16-N16+O15) -> 268.9 | X16: 14 | AE16: =SUM(AC16:AD16) -> 0 | AJ16: =AE16 -> 0
A17: 44909 | F17: =SUM(B17:E17) -> 0 | G17: =F17 -> 0 | K17: =SUM(F17-H17-J17-I17) -> 0 | L17: =SUM(F17-H17-J17-I17) -> 0 | O17: =SUM(L17-M17-N17+O16+P17) -> 268.9 | X17: 15 | AE17: =SUM(AC17:AD17) -> 0 | AJ17: =AE17 -> 0
A18: 44910 | F18: =SUM(B18:E18) -> 0 | G18: =F18 -> 0 | K18: =SUM(F18-H18-J18-I18) -> 0 | L18: =SUM(F18-H18-J18-I18) -> 0 | O18: =SUM(L18-M18-N18+O17+P18) -> 268.9 | X18: 16 | AE18: =SUM(AC18:AD18) -> 0 | AJ18: =AE18 -> 0
A19: 44911 | F19: =SUM(B19:E19) -> 0 | G19: =F19 -> 0 | K19: =SUM(F19-H19-J19-I19) -> 0 | L19: =SUM(F19-H19-J19-I19) -> 0 | O19: =SUM(L19-M19-N19+O18+P19) -> 268.9 | X19: 17 | AE19: =SUM(AC19:AD19) -> 0 | AJ19: =AE19 -> 0
A20: 44912 | F20: =SUM(B20:E20) -> 0 | G20: =F20 -> 0 | K20: =SUM(F20-H20-J20-I20) -> 0 | L20: =SUM(F20-H20-J20-I20) -> 0 | O20: =SUM(L20-M20-N20+O19+P20) -> 268.9 | X20: 18 | AE20: =SUM(AC20:AD20) -> 0 | AJ20: =AE20 -> 0
A21: 44913 | F21: =SUM(B21:E21) -> 0 | G21: =F21 -> 0 | K21: =SUM(F21-H21-J21-I21) -> 0 | L21: =SUM(F21-H21-J21-I21) -> 0 | O21: =SUM(L21-M21-N21+O20) -> 268.9 | X21: 19 | AE21: =SUM(AC21:AD21) -> 0 | AJ21: =AE21 -> 0
A22: 44914 | F22: =SUM(B22:E22) -> 0 | G22: =F22 -> 0 | K22: =SUM(F22-H22-J22-I22) -> 0 | L22: =SUM(F22-H22-J22-I22) -> 0 | O22: =SUM(L22-M22-N22+O21) -> 268.9 | X22: 20 | AE22: =SUM(AC22:AD22) -> 0 | AJ22: =AE22 -> 0
A23: 44915 | F23: =SUM(B23:E23) -> 0 | G23: =F23 -> 0 | K23: =SUM(F23-H23-J23-I23) -> 0 | L23: =SUM(F23-H23-J23-I23) -> 0 | O23: =SUM(L23-M23-N23+O22) -> 268.9 | X23: 21 | AE23: =SUM(AC23:AD23) -> 0 | AJ23: =AE23 -> 0
A24: 44916 | F24: =SUM(B24:E24) -> 0 | G24: =F24 -> 0 | K24: =SUM(F24-H24-J24-I24) -> 0 | L24: =SUM(F24-H24-J24-I24) -> 0 | O24: =SUM(L24-M24-N24+O23+P24) -> 268.9 | X24: 22 | AE24: =SUM(AC24:AD24) -> 0 | AJ24: =AE24 -> 0
A25: 44917 | F25: =SUM(B25:E25) -> 0 | G25: =F25 -> 0 | K25: =SUM(F25-H25-J25-I25) -> 0 | L25: =SUM(F25-H25-J25-I25) -> 0 | O25: =SUM(L25-M25-N25+O24) -> 268.9 | X25: 26 | AE25: =SUM(AC25:AD25) -> 0 | AJ25: =AE25 -> 0
A26: 44918 | F26: =SUM(B26:E26) -> 0 | G26: =F26 -> 0 | K26: =SUM(F26-H26-J26-I26) -> 0 | L26: =SUM(F26-H26-J26-I26) -> 0 | O26: =SUM(L26-M26-N26+O25) -> 268.9 | X26: 27 | AE26: =SUM(AC26:AD26) -> 0 | AJ26: =AE26 -> 0
A27: 44919 | F27: =SUM(B27:E27) -> 0 | G27: =F27 -> 0 | K27: =SUM(F27-H27-J27-I27) -> 0 | L27: =SUM(F27-H27-J27-I27) -> 0 | O27: =SUM(L27-M27-N27+O26) -> 268.9 | X27: 28 | AE27: =SUM(AC27:AD27) -> 0 | AJ27: =AE27 -> 0
A28: 44920 | F28: =SUM(B28:E28) -> 0 | G28: =F28 -> 0 | K28: =SUM(F28-H28-J28-I28) -> 0 | L28: =SUM(F28-H28-J28-I28) -> 0 | O28: =SUM(L28-M28-N28+O27+P28) -> 268.9 | X28: 29 | AE28: =SUM(AC28:AD28) -> 0 | AJ28: =AE28 -> 0
A29: 44921 | F29: =SUM(B29:E29) -> 0 | G29: =F29 -> 0 | K29: =SUM(F29-H29-J29-I29) -> 0 | L29: =SUM(F29-H29-J29-I29) -> 0 | O29: =SUM(L29-M29-N29+O28) -> 268.9 | X29: 30 | AE29: =SUM(AC29:AD29) -> 0 | AJ29: =AE29 -> 0
A30: 44922 | F30: =SUM(B30:E30) -> 0 | G30: =F30 -> 0 | K30: =SUM(F30-H30-J30-I30) -> 0 | L30: =SUM(F30-H30-J30-I30) -> 0 | O30: =SUM(L30-M30-N30+O29+P30) -> 268.9 | AC30: TVA | AD30: =SUM(AD3:AD29) -> 0
A31: 44923 | F31: =SUM(B31:E31) -> 0 | G31: =F31 -> 0 | K31: =SUM(F31-H31-J31-I31) -> 0 | L31: =SUM(F31-H31-J31-I31) -> 0 | O31: =SUM(L31-M31-N31+O30) -> 268.9 | P31: SOLDE CAISSE
A32: 44924 | F32: =SUM(B32:E32) -> 0 | G32: =F32 -> 0 | K32: =SUM(F32-H32-J32-I32) -> 0 | L32: =SUM(F32-H32-J32-I32) -> 0 | O32: =SUM(L32-M32-N32+O31) -> 268.9 | P32: DU MOIS | AA32: MARGE | AL32: calcul de marge
A33: 44925 | F33: =SUM(B33:E33) -> 0 | G33: =F33 -> 0 | K33: =SUM(F33-H33-J33-I33) -> 0 | L33: =SUM(F33-H33-J33-I33) -> 0 | O33: =SUM(L33-M33-N33+O32) -> 268.9 | P33: =SUM(O33) -> 268.9 | X33: 1 | AE33: =SUM(AC33:AD33) -> 0 | AJ33: 0 | AL33: =AC33 -> 0 | AM33: 1
B34: =SUM(B5:B33) -> 0 | C34: =SUM(C3:C33) -> 0 | D34: =SUM(D3:D33) -> 0 | E34: =SUM(E3:E33) -> 0 | F34: =SUM(F3:F33) -> 0 | H34: =SUM(H3:H33) -> 0 | J34: =SUM(J3:J33) -> 0 | K34: =SUM(K3:K33) -> 0 | L34: =SUM(L3:L33) -> 0 | M34: =SUM(M3:M33) -> 0 | N34: =SUM(N3:N33) -> 0 | X34: 2 | AE34: =SUM(AC34:AD34) -> 0 | AJ34: =AE34 -> 0 | AL34: =AC34 -> 0 | AM34: 2
A35: HTVA | B35: =SUM(B3:B33) -> 0 | C35: =SUM(C34/1.06) -> 0 | D35: =SUM(D34/1.12) -> 0 | E35: =SUM(E34/1.21) -> 0 | F35: =SUM(B35:E35) -> 0 | G35: =SUM(G34:G34) -> 0 | L35: TOTAL SORTIE | N35: =SUM(M34:N34) -> 0 | X35: 3 | AE35: =SUM(AC35:AD35) -> 0 | AJ35: =AE35 -> 0 | AL35: =AC35 -> 0 | AM35: 3
A36: TVA | C36: =SUM(C34-C35) -> 0 | D36: =SUM(D34-D35) -> 0 | E36: =SUM(E34-E35) -> 0 | F36: =SUM(C36:E36) -> 0 | X36: 4 | AE36: =SUM(AC36:AD36) -> 0 | AJ36: 0 | AL36: =AC36 -> 0 | AM36: 4
X37: 5 | AE37: =SUM(AC37:AD37) -> 0 | AJ37: =AE37 -> 0 | AL37: =AC37 -> 0 | AM37: 5
X38: 6 | AE38: =SUM(AC38:AD38) -> 0 | AJ38: 0 | AL38: =AC38 -> 0 | AM38: 6
X39: 7 | AE39: =SUM(AC39:AD39) -> 0 | AJ39: =AE39 -> 0 | AL39: =AC39 -> 0 | AM39: 7
X40: 8 | AE40: =SUM(AC40:AD40) -> 0 | AJ40: =AE40 -> 0 | AL40: =AC40 -> 0 | AM40: 8
...

Sheet NOV 2026
A1: 44865 | C1: RECETTE | G1: CAISSE | M1: MOUVEMENT CAISSE | P1: CAISSE MOIS PREC | Q1: PAYEMENT FOURNISSEUR CAISSE | R1: MONTANT | S1: TOTAL | T1: DATE SORTIE | Y1: FOURNISSEUR | Z1: DATE | AA1: REFERENCE | AB1: COMPTE | AC1: HTVA | AD1: TVA | AE1: MONTANT | AF1: PAIEMENT | AG1: CAISSE | AH1: DATE | AI1: ECHEANCE
A2: DATE | B2: FACTURE | C2: 6 | D2: 12 | E2: 21 | F2: TOTAL | G2: CHIFF | H2: carte | I2: cadeau0 | J2: bque | K2: liquide | L2: TOT CAIS | M2: SORTIE | N2: vers ban | O2: solde cai | P2: ='OCT 2026'!P33 -> 268.9 | AB2: 44865
A3: 44865 | F3: =SUM(B3:E3) -> 0 | G3: =F3 -> 0 | K3: =SUM(F3-H3-J3-I3) -> 0 | L3: =SUM(F3-H3-J3-I3) -> 0 | O3: =SUM(L3-M3-N3+P2) -> 268.9 | X3: 1 | AE3: =SUM(AC3:AD3) -> 0 | AJ3: 0
A4: 44866 | F4: =SUM(B4:E4) -> 0 | G4: =F4 -> 0 | K4: =SUM(F4-H4-J4-I4) -> 0 | L4: =SUM(F4-H4-J4-I4) -> 0 | O4: =SUM(L4-M4-N4+O3+P4) -> 268.9 | X4: 2 | AE4: =SUM(AC4:AD4) -> 0 | AJ4: =AE4 -> 0
A5: 44867 | F5: =SUM(B5:E5) -> 0 | G5: =F5 -> 0 | K5: =SUM(F5-H5-J5-I5) -> 0 | L5: =SUM(F5-H5-J5-I5) -> 0 | O5: =SUM(L5-M5-N5+O4+P5) -> 268.9 | X5: 3 | AE5: =SUM(AC5:AD5) -> 0 | AJ5: 0
A6: 44868 | F6: =SUM(B6:E6) -> 0 | G6: =F6 -> 0 | K6: =SUM(F6-H6-J6-I6) -> 0 | L6: =SUM(F6-H6-J6-I6) -> 0 | O6: =SUM(L6-M6-N6+O5+P6) -> 268.9 | X6: 4 | AE6: =SUM(AC6:AD6) -> 0 | AJ6: 0
A7: 44869 | F7: =SUM(B7:E7) -> 0 | G7: =F7 -> 0 | K7: =SUM(F7-H7-J7-I7) -> 0 | L7: =SUM(F7-H7-J7-I7) -> 0 | O7: =SUM(L7-M7-N7+O6+P7) -> 268.9 | X7: 5 | AE7: =SUM(AC7:AD7) -> 0 | AJ7: 0
A8: 44870 | F8: =SUM(B8:E8) -> 0 | G8: =F8 -> 0 | K8: =SUM(F8-H8-J8-I8) -> 0 | L8: =SUM(F8-H8-J8-I8) -> 0 | O8: =SUM(L8-M8-N8+O7+P8) -> 268.9 | X8: 6 | AE8: =SUM(AC8:AD8) -> 0 | AJ8: 0
A9: 44871 | F9: =SUM(B9:E9) -> 0 | G9: =F9 -> 0 | K9: =SUM(F9-H9-J9-I9) -> 0 | L9: =SUM(F9-H9-J9-I9) -> 0 | O9: =SUM(L9-M9-N9+O8) -> 268.9 | X9: 7 | AE9: =SUM(AC9:AD9) -> 0 | AJ9: =AE9 -> 0
A10: 44872 | F10: =SUM(B10:E10) -> 0 | G10: =F10 -> 0 | K10: =SUM(F10-H10-J10-I10) -> 0 | L10: =SUM(F10-H10-J10-I10) -> 0 | O10: =SUM(L10-M10-N10+O9) -> 268.9 | X10: 8 | AE10: =SUM(AC10:AD10) -> 0 | AJ10: =AE10 -> 0
A11: 44873 | F11: =SUM(B11:E11) -> 0 | G11: =F11 -> 0 | K11: =SUM(F11-H11-J11-I11) -> 0 | L11: =SUM(F11-H11-J11-I11) -> 0 | O11: =SUM(L11-M11-N11+O10) -> 268.9 | X11: 9 | AE11: =SUM(AC11:AD11) -> 0 | AJ11: =AE11 -> 0
A12: 44874 | F12: =SUM(B12:E12) -> 0 | G12: =F12 -> 0 | K12: =SUM(F12-H12-J12-I12) -> 0 | L12: =SUM(F12-H12-J12-I12) -> 0 | O12: =SUM(L12-M12-N12+O11) -> 268.9 | X12: 10 | AE12: =SUM(AC12:AD12) -> 0 | AJ12: =AE12 -> 0
A13: 44875 | F13: =SUM(B13:E13) -> 0 | G13: =F13 -> 0 | K13: =SUM(F13-H13-J13-I13) -> 0 | L13: =SUM(F13-H13-J13-I13) -> 0 | O13: =SUM(L13-M13-N13+O12) -> 268.9 | X13: 11 | AE13: =SUM(AC13:AD13) -> 0 | AJ13: =AE13 -> 0
A14: 44876 | F14: =SUM(B14:E14) -> 0 | G14: =F14 -> 0 | K14: =SUM(F14-H14-J14-I14) -> 0 | L14: =SUM(F14-H14-J14-I14) -> 0 | O14: =SUM(L14-M14-N14+O13) -> 268.9 | X14: 12 | AE14: =SUM(AC14:AD14) -> 0 | AJ14: =AE14 -> 0
A15: 44877 | F15: =SUM(B15:E15) -> 0 | G15: =F15 -> 0 | K15: =SUM(F15-H15-J15-I15) -> 0 | L15: =SUM(F15-H15-J15-I15) -> 0 | O15: =SUM(L15-M15-N15+O14) -> 268.9 | X15: 13 | AE15: =SUM(AC15:AD15) -> 0 | AJ15: =AE15 -> 0
A16: 44878 | F16: =SUM(B16:E16) -> 0 | G16: =F16 -> 0 | K16: =SUM(F16-H16-J16-I16) -> 0 | L16: =SUM(F16-H16-J16-I16) -> 0 | O16: =SUM(L16-M16-N16+O15) -> 268.9 | X16: 14 | AE16: =SUM(AC16:AD16) -> 0 | AJ16: =AE16 -> 0
A17: 44879 | F17: =SUM(B17:E17) -> 0 | G17: =F17 -> 0 | K17: =SUM(F17-H17-J17-I17) -> 0 | L17: =SUM(F17-H17-J17-I17) -> 0 | O17: =SUM(L17-M17-N17+O16+P17) -> 268.9 | X17: 15 | AE17: =SUM(AC17:AD17) -> 0 | AJ17: =AE17 -> 0
A18: 44880 | F18: =SUM(B18:E18) -> 0 | G18: =F18 -> 0 | K18: =SUM(F18-H18-J18-I18) -> 0 | L18: =SUM(F18-H18-J18-I18) -> 0 | O18: =SUM(L18-M18-N18+O17+P18) -> 268.9 | X18: 16 | AE18: =SUM(AC18:AD18) -> 0 | AJ18: =AE18 -> 0
A19: 44881 | F19: =SUM(B19:E19) -> 0 | G19: =F19 -> 0 | K19: =SUM(F19-H19-J19-I19) -> 0 | L19: =SUM(F19-H19-J19-I19) -> 0 | O19: =SUM(L19-M19-N19+O18+P19) -> 268.9 | X19: 17 | AE19: =SUM(AC19:AD19) -> 0 | AJ19: =AE19 -> 0
A20: 44882 | F20: =SUM(B20:E20) -> 0 | G20: =F20 -> 0 | K20: =SUM(F20-H20-J20-I20) -> 0 | L20: =SUM(F20-H20-J20-I20) -> 0 | O20: =SUM(L20-M20-N20+O19+P20) -> 268.9 | X20: 18 | AE20: =SUM(AC20:AD20) -> 0 | AJ20: =AE20 -> 0
A21: 44883 | F21: =SUM(B21:E21) -> 0 | G21: =F21 -> 0 | K21: =SUM(F21-H21-J21-I21) -> 0 | L21: =SUM(F21-H21-J21-I21) -> 0 | O21: =SUM(L21-M21-N21+O20) -> 268.9 | X21: 19 | AE21: =SUM(AC21:AD21) -> 0 | AJ21: =AE21 -> 0
A22: 44884 | F22: =SUM(B22:E22) -> 0 | G22: =F22 -> 0 | K22: =SUM(F22-H22-J22-I22) -> 0 | L22: =SUM(F22-H22-J22-I22) -> 0 | O22: =SUM(L22-M22-N22+O21) -> 268.9 | X22: 20 | AE22: =SUM(AC22:AD22) -> 0 | AJ22: =AE22 -> 0
A23: 44885 | F23: =SUM(B23:E23) -> 0 | G23: =F23 -> 0 | K23: =SUM(F23-H23-J23-I23) -> 0 | L23: =SUM(F23-H23-J23-I23) -> 0 | O23: =SUM(L23-M23-N23+O22) -> 268.9 | X23: 21 | AE23: =SUM(AC23:AD23) -> 0 | AJ23: =AE23 -> 0
A24: 44886 | F24: =SUM(B24:E24) -> 0 | G24: =F24 -> 0 | K24: =SUM(F24-H24-J24-I24) -> 0 | L24: =SUM(F24-H24-J24-I24) -> 0 | O24: =SUM(L24-M24-N24+O23+P24) -> 268.9 | X24: 22 | AE24: =SUM(AC24:AD24) -> 0 | AJ24: =AE24 -> 0
A25: 44887 | F25: =SUM(B25:E25) -> 0 | G25: =F25 -> 0 | K25: =SUM(F25-H25-J25-I25) -> 0 | L25: =SUM(F25-H25-J25-I25) -> 0 | O25: =SUM(L25-M25-N25+O24) -> 268.9 | X25: 26 | AE25: =SUM(AC25:AD25) -> 0 | AJ25: =AE25 -> 0
A26: 44888 | F26: =SUM(B26:E26) -> 0 | G26: =F26 -> 0 | K26: =SUM(F26-H26-J26-I26) -> 0 | L26: =SUM(F26-H26-J26-I26) -> 0 | O26: =SUM(L26-M26-N26+O25) -> 268.9 | X26: 27 | AE26: =SUM(AC26:AD26) -> 0 | AJ26: =AE26 -> 0
A27: 44889 | F27: =SUM(B27:E27) -> 0 | G27: =F27 -> 0 | K27: =SUM(F27-H27-J27-I27) -> 0 | L27: =SUM(F27-H27-J27-I27) -> 0 | O27: =SUM(L27-M27-N27+O26) -> 268.9 | X27: 28 | AE27: =SUM(AC27:AD27) -> 0 | AJ27: =AE27 -> 0
A28: 44890 | F28: =SUM(B28:E28) -> 0 | G28: =F28 -> 0 | K28: =SUM(F28-H28-J28-I28) -> 0 | L28: =SUM(F28-H28-J28-I28) -> 0 | O28: =SUM(L28-M28-N28+O27+P28) -> 268.9 | X28: 29 | AE28: =SUM(AC28:AD28) -> 0 | AJ28: =AE28 -> 0
A29: 44891 | F29: =SUM(B29:E29) -> 0 | G29: =F29 -> 0 | K29: =SUM(F29-H29-J29-I29) -> 0 | L29: =SUM(F29-H29-J29-I29) -> 0 | O29: =SUM(L29-M29-N29+O28) -> 268.9 | X29: 30 | AE29: =SUM(AC29:AD29) -> 0 | AJ29: =AE29 -> 0
A30: 44892 | F30: =SUM(B30:E30) -> 0 | G30: =F30 -> 0 | K30: =SUM(F30-H30-J30-I30) -> 0 | L30: =SUM(F30-H30-J30-I30) -> 0 | O30: =SUM(L30-M30-N30+O29+P30) -> 268.9 | AC30: TVA | AD30: =SUM(AD3:AD29) -> 0
A31: 44893 | F31: =SUM(B31:E31) -> 0 | G31: =F31 -> 0 | K31: =SUM(F31-H31-J31-I31) -> 0 | L31: =SUM(F31-H31-J31-I31) -> 0 | O31: =SUM(L31-M31-N31+O30) -> 268.9 | P31: SOLDE CAISSE
A32: 44894 | F32: =SUM(B32:E32) -> 0 | G32: =F32 -> 0 | K32: =SUM(F32-H32-J32-I32) -> 0 | L32: =SUM(F32-H32-J32-I32) -> 0 | O32: =SUM(L32-M32-N32+O31) -> 268.9 | P32: DU MOIS | AA32: MARGE | AL32: calcul de marge
A33: 44895 | F33: =SUM(B33:E33) -> 0 | G33: =F33 -> 0 | K33: =SUM(F33-H33-J33-I33) -> 0 | L33: =SUM(F33-H33-J33-I33) -> 0 | O33: =SUM(L33-M33-N33+O32) -> 268.9 | P33: =SUM(O33) -> 268.9 | X33: 1 | AE33: =SUM(AC33:AD33) -> 0 | AJ33: 0 | AL33: =AC33 -> 0 | AM33: 1
B34: =SUM(B5:B33) -> 0 | C34: =SUM(C3:C33) -> 0 | D34: =SUM(D3:D33) -> 0 | E34: =SUM(E3:E33) -> 0 | F34: =SUM(F3:F33) -> 0 | H34: =SUM(H3:H33) -> 0 | J34: =SUM(J3:J33) -> 0 | K34: =SUM(K3:K33) -> 0 | L34: =SUM(L3:L33) -> 0 | M34: =SUM(M3:M33) -> 0 | N34: =SUM(N3:N33) -> 0 | X34: 2 | AE34: =SUM(AC34:AD34) -> 0 | AJ34: =AE34 -> 0 | AL34: =AC34 -> 0 | AM34: 2
A35: HTVA | B35: =SUM(B3:B33) -> 0 | C35: =SUM(C34/1.06) -> 0 | D35: =SUM(D34/1.12) -> 0 | E35: =SUM(E34/1.21) -> 0 | F35: =SUM(B35:E35) -> 0 | G35: =SUM(G34:G34) -> 0 | L35: TOTAL SORTIE | N35: =SUM(M34:N34) -> 0 | X35: 3 | AE35: =SUM(AC35:AD35) -> 0 | AJ35: =AE35 -> 0 | AL35: =AC35 -> 0 | AM35: 3
A36: TVA | C36: =SUM(C34-C35) -> 0 | D36: =SUM(D34-D35) -> 0 | E36: =SUM(E34-E35) -> 0 | F36: =SUM(C36:E36) -> 0 | X36: 4 | AE36: =SUM(AC36:AD36) -> 0 | AJ36: 0 | AL36: =AC36 -> 0 | AM36: 4
X37: 5 | AE37: =SUM(AC37:AD37) -> 0 | AJ37: =AE37 -> 0 | AL37: =AC37 -> 0 | AM37: 5
X38: 6 | AE38: =SUM(AC38:AD38) -> 0 | AJ38: 0 | AL38: =AC38 -> 0 | AM38: 6
X39: 7 | AE39: =SUM(AC39:AD39) -> 0 | AJ39: =AE39 -> 0 | AL39: =AC39 -> 0 | AM39: 7
X40: 8 | AE40: =SUM(AC40:AD40) -> 0 | AJ40: =AE40 -> 0 | AL40: =AC40 -> 0 | AM40: 8
...

Sheet OCT 2026
A1: 44834 | C1: RECETTE | G1: CAISSE | M1: MOUVEMENT CAISSE | P1: CAISSE MOIS PREC | Q1: PAYEMENT FOURNISSEUR CAISSE | R1: MONTANT | S1: TOTAL | T1: DATE SORTIE | Y1: FOURNISSEUR | Z1: DATE | AA1: REFERENCE | AB1: COMPTE | AC1: HTVA | AD1: TVA | AE1: MONTANT | AF1: PAIEMENT | AG1: CAISSE | AH1: DATE | AI1: ECHEANCE
A2: DATE | B2: FACTURE | C2: 6 | D2: 12 | E2: 21 | F2: TOTAL | G2: CHIFF | H2: carte | I2: cadeau0 | J2: bque | K2: liquide | L2: TOT CAIS | M2: SORTIE | N2: vers ban | O2: solde cai | P2: ='SEPT 2026'!P33 -> 268.9 | AB2: 44834
A3: 44834 | F3: =SUM(B3:E3) -> 0 | G3: =F3 -> 0 | K3: =SUM(F3-H3-J3-I3) -> 0 | L3: =SUM(F3-H3-J3-I3) -> 0 | O3: =SUM(L3-M3-N3+P2) -> 268.9 | X3: 1 | AE3: =SUM(AC3:AD3) -> 0 | AJ3: 0
A4: 44835 | F4: =SUM(B4:E4) -> 0 | G4: =F4 -> 0 | K4: =SUM(F4-H4-J4-I4) -> 0 | L4: =SUM(F4-H4-J4-I4) -> 0 | O4: =SUM(L4-M4-N4+O3+P4) -> 268.9 | X4: 2 | AE4: =SUM(AC4:AD4) -> 0 | AJ4: =AE4 -> 0
A5: 44836 | F5: =SUM(B5:E5) -> 0 | G5: =F5 -> 0 | K5: =SUM(F5-H5-J5-I5) -> 0 | L5: =SUM(F5-H5-J5-I5) -> 0 | O5: =SUM(L5-M5-N5+O4+P5) -> 268.9 | X5: 3 | AE5: =SUM(AC5:AD5) -> 0 | AJ5: 0
A6: 44837 | F6: =SUM(B6:E6) -> 0 | G6: =F6 -> 0 | K6: =SUM(F6-H6-J6-I6) -> 0 | L6: =SUM(F6-H6-J6-I6) -> 0 | O6: =SUM(L6-M6-N6+O5+P6) -> 268.9 | X6: 4 | AE6: =SUM(AC6:AD6) -> 0 | AJ6: 0
A7: 44838 | F7: =SUM(B7:E7) -> 0 | G7: =F7 -> 0 | K7: =SUM(F7-H7-J7-I7) -> 0 | L7: =SUM(F7-H7-J7-I7) -> 0 | O7: =SUM(L7-M7-N7+O6+P7) -> 268.9 | X7: 5 | AE7: =SUM(AC7:AD7) -> 0 | AJ7: 0
A8: 44839 | F8: =SUM(B8:E8) -> 0 | G8: =F8 -> 0 | K8: =SUM(F8-H8-J8-I8) -> 0 | L8: =SUM(F8-H8-J8-I8) -> 0 | O8: =SUM(L8-M8-N8+O7+P8) -> 268.9 | X8: 6 | AE8: =SUM(AC8:AD8) -> 0 | AJ8: 0
A9: 44840 | F9: =SUM(B9:E9) -> 0 | G9: =F9 -> 0 | K9: =SUM(F9-H9-J9-I9) -> 0 | L9: =SUM(F9-H9-J9-I9) -> 0 | O9: =SUM(L9-M9-N9+O8) -> 268.9 | X9: 7 | AE9: =SUM(AC9:AD9) -> 0 | AJ9: =AE9 -> 0
A10: 44841 | F10: =SUM(B10:E10) -> 0 | G10: =F10 -> 0 | K10: =SUM(F10-H10-J10-I10) -> 0 | L10: =SUM(F10-H10-J10-I10) -> 0 | O10: =SUM(L10-M10-N10+O9) -> 268.9 | X10: 8 | AE10: =SUM(AC10:AD10) -> 0 | AJ10: =AE10 -> 0
A11: 44842 | F11: =SUM(B11:E11) -> 0 | G11: =F11 -> 0 | K11: =SUM(F11-H11-J11-I11) -> 0 | L11: =SUM(F11-H11-J11-I11) -> 0 | O11: =SUM(L11-M11-N11+O10) -> 268.9 | X11: 9 | AE11: =SUM(AC11:AD11) -> 0 | AJ11: =AE11 -> 0
A12: 44843 | F12: =SUM(B12:E12) -> 0 | G12: =F12 -> 0 | K12: =SUM(F12-H12-J12-I12) -> 0 | L12: =SUM(F12-H12-J12-I12) -> 0 | O12: =SUM(L12-M12-N12+O11) -> 268.9 | X12: 10 | AE12: =SUM(AC12:AD12) -> 0 | AJ12: =AE12 -> 0
A13: 44844 | F13: =SUM(B13:E13) -> 0 | G13: =F13 -> 0 | K13: =SUM(F13-H13-J13-I13) -> 0 | L13: =SUM(F13-H13-J13-I13) -> 0 | O13: =SUM(L13-M13-N13+O12) -> 268.9 | X13: 11 | AE13: =SUM(AC13:AD13) -> 0 | AJ13: =AE13 -> 0
A14: 44845 | F14: =SUM(B14:E14) -> 0 | G14: =F14 -> 0 | K14: =SUM(F14-H14-J14-I14) -> 0 | L14: =SUM(F14-H14-J14-I14) -> 0 | O14: =SUM(L14-M14-N14+O13) -> 268.9 | X14: 12 | AE14: =SUM(AC14:AD14) -> 0 | AJ14: =AE14 -> 0
A15: 44846 | F15: =SUM(B15:E15) -> 0 | G15: =F15 -> 0 | K15: =SUM(F15-H15-J15-I15) -> 0 | L15: =SUM(F15-H15-J15-I15) -> 0 | O15: =SUM(L15-M15-N15+O14) -> 268.9 | X15: 13 | AE15: =SUM(AC15:AD15) -> 0 | AJ15: =AE15 -> 0
A16: 44847 | F16: =SUM(B16:E16) -> 0 | G16: =F16 -> 0 | K16: =SUM(F16-H16-J16-I16) -> 0 | L16: =SUM(F16-H16-J16-I16) -> 0 | O16: =SUM(L16-M16-N16+O15) -> 268.9 | X16: 14 | AE16: =SUM(AC16:AD16) -> 0 | AJ16: =AE16 -> 0
A17: 44848 | F17: =SUM(B17:E17) -> 0 | G17: =F17 -> 0 | K17: =SUM(F17-H17-J17-I17) -> 0 | L17: =SUM(F17-H17-J17-I17) -> 0 | O17: =SUM(L17-M17-N17+O16+P17) -> 268.9 | X17: 15 | AE17: =SUM(AC17:AD17) -> 0 | AJ17: =AE17 -> 0
A18: 44849 | F18: =SUM(B18:E18) -> 0 | G18: =F18 -> 0 | K18: =SUM(F18-H18-J18-I18) -> 0 | L18: =SUM(F18-H18-J18-I18) -> 0 | O18: =SUM(L18-M18-N18+O17+P18) -> 268.9 | X18: 16 | AE18: =SUM(AC18:AD18) -> 0 | AJ18: =AE18 -> 0
A19: 44850 | F19: =SUM(B19:E19) -> 0 | G19: =F19 -> 0 | K19: =SUM(F19-H19-J19-I19) -> 0 | L19: =SUM(F19-H19-J19-I19) -> 0 | O19: =SUM(L19-M19-N19+O18+P19) -> 268.9 | X19: 17 | AE19: =SUM(AC19:AD19) -> 0 | AJ19: =AE19 -> 0
A20: 44851 | F20: =SUM(B20:E20) -> 0 | G20: =F20 -> 0 | K20: =SUM(F20-H20-J20-I20) -> 0 | L20: =SUM(F20-H20-J20-I20) -> 0 | O20: =SUM(L20-M20-N20+O19+P20) -> 268.9 | X20: 18 | AE20: =SUM(AC20:AD20) -> 0 | AJ20: =AE20 -> 0
A21: 44852 | F21: =SUM(B21:E21) -> 0 | G21: =F21 -> 0 | K21: =SUM(F21-H21-J21-I21) -> 0 | L21: =SUM(F21-H21-J21-I21) -> 0 | O21: =SUM(L21-M21-N21+O20) -> 268.9 | X21: 19 | AE21: =SUM(AC21:AD21) -> 0 | AJ21: =AE21 -> 0
A22: 44853 | F22: =SUM(B22:E22) -> 0 | G22: =F22 -> 0 | K22: =SUM(F22-H22-J22-I22) -> 0 | L22: =SUM(F22-H22-J22-I22) -> 0 | O22: =SUM(L22-M22-N22+O21) -> 268.9 | X22: 20 | AE22: =SUM(AC22:AD22) -> 0 | AJ22: =AE22 -> 0
A23: 44854 | F23: =SUM(B23:E23) -> 0 | G23: =F23 -> 0 | K23: =SUM(F23-H23-J23-I23) -> 0 | L23: =SUM(F23-H23-J23-I23) -> 0 | O23: =SUM(L23-M23-N23+O22) -> 268.9 | X23: 21 | AE23: =SUM(AC23:AD23) -> 0 | AJ23: =AE23 -> 0
A24: 44855 | F24: =SUM(B24:E24) -> 0 | G24: =F24 -> 0 | K24: =SUM(F24-H24-J24-I24) -> 0 | L24: =SUM(F24-H24-J24-I24) -> 0 | O24: =SUM(L24-M24-N24+O23+P24) -> 268.9 | X24: 22 | AE24: =SUM(AC24:AD24) -> 0 | AJ24: =AE24 -> 0
A25: 44856 | F25: =SUM(B25:E25) -> 0 | G25: =F25 -> 0 | K25: =SUM(F25-H25-J25-I25) -> 0 | L25: =SUM(F25-H25-J25-I25) -> 0 | O25: =SUM(L25-M25-N25+O24) -> 268.9 | X25: 26 | AE25: =SUM(AC25:AD25) -> 0 | AJ25: =AE25 -> 0
A26: 44857 | F26: =SUM(B26:E26) -> 0 | G26: =F26 -> 0 | K26: =SUM(F26-H26-J26-I26) -> 0 | L26: =SUM(F26-H26-J26-I26) -> 0 | O26: =SUM(L26-M26-N26+O25) -> 268.9 | X26: 27 | AE26: =SUM(AC26:AD26) -> 0 | AJ26: =AE26 -> 0
A27: 44858 | F27: =SUM(B27:E27) -> 0 | G27: =F27 -> 0 | K27: =SUM(F27-H27-J27-I27) -> 0 | L27: =SUM(F27-H27-J27-I27) -> 0 | O27: =SUM(L27-M27-N27+O26) -> 268.9 | X27: 28 | AE27: =SUM(AC27:AD27) -> 0 | AJ27: =AE27 -> 0
A28: 44859 | F28: =SUM(B28:E28) -> 0 | G28: =F28 -> 0 | K28: =SUM(F28-H28-J28-I28) -> 0 | L28: =SUM(F28-H28-J28-I28) -> 0 | O28: =SUM(L28-M28-N28+O27+P28) -> 268.9 | X28: 29 | AE28: =SUM(AC28:AD28) -> 0 | AJ28: =AE28 -> 0
A29: 44860 | F29: =SUM(B29:E29) -> 0 | G29: =F29 -> 0 | K29: =SUM(F29-H29-J29-I29) -> 0 | L29: =SUM(F29-H29-J29-I29) -> 0 | O29: =SUM(L29-M29-N29+O28) -> 268.9 | X29: 30 | AE29: =SUM(AC29:AD29) -> 0 | AJ29: =AE29 -> 0
A30: 44861 | F30: =SUM(B30:E30) -> 0 | G30: =F30 -> 0 | K30: =SUM(F30-H30-J30-I30) -> 0 | L30: =SUM(F30-H30-J30-I30) -> 0 | O30: =SUM(L30-M30-N30+O29+P30) -> 268.9 | AC30: TVA | AD30: =SUM(AD3:AD29) -> 0
A31: 44862 | F31: =SUM(B31:E31) -> 0 | G31: =F31 -> 0 | K31: =SUM(F31-H31-J31-I31) -> 0 | L31: =SUM(F31-H31-J31-I31) -> 0 | O31: =SUM(L31-M31-N31+O30) -> 268.9 | P31: SOLDE CAISSE
A32: 44863 | F32: =SUM(B32:E32) -> 0 | G32: =F32 -> 0 | K32: =SUM(F32-H32-J32-I32) -> 0 | L32: =SUM(F32-H32-J32-I32) -> 0 | O32: =SUM(L32-M32-N32+O31) -> 268.9 | P32: DU MOIS | AA32: MARGE | AL32: calcul de marge
A33: 44864 | F33: =SUM(B33:E33) -> 0 | G33: =F33 -> 0 | K33: =SUM(F33-H33-J33-I33) -> 0 | L33: =SUM(F33-H33-J33-I33) -> 0 | O33: =SUM(L33-M33-N33+O32) -> 268.9 | P33: =SUM(O33) -> 268.9 | X33: 1 | AE33: =SUM(AC33:AD33) -> 0 | AJ33: 0 | AL33: =AC33 -> 0 | AM33: 1
B34: =SUM(B5:B33) -> 0 | C34: =SUM(C3:C33) -> 0 | D34: =SUM(D3:D33) -> 0 | E34: =SUM(E3:E33) -> 0 | F34: =SUM(F3:F33) -> 0 | H34: =SUM(H3:H33) -> 0 | J34: =SUM(J3:J33) -> 0 | K34: =SUM(K3:K33) -> 0 | L34: =SUM(L3:L33) -> 0 | M34: =SUM(M3:M33) -> 0 | N34: =SUM(N3:N33) -> 0 | X34: 2 | AE34: =SUM(AC34:AD34) -> 0 | AJ34: =AE34 -> 0 | AL34: =AC34 -> 0 | AM34: 2
A35: HTVA | B35: =SUM(B3:B33) -> 0 | C35: =SUM(C34/1.06) -> 0 | D35: =SUM(D34/1.12) -> 0 | E35: =SUM(E34/1.21) -> 0 | F35: =SUM(B35:E35) -> 0 | G35: =SUM(G34:G34) -> 0 | L35: TOTAL SORTIE | N35: =SUM(M34:N34) -> 0 | X35: 3 | AE35: =SUM(AC35:AD35) -> 0 | AJ35: =AE35 -> 0 | AL35: =AC35 -> 0 | AM35: 3
A36: TVA | C36: =SUM(C34-C35) -> 0 | D36: =SUM(D34-D35) -> 0 | E36: =SUM(E34-E35) -> 0 | F36: =SUM(C36:E36) -> 0 | X36: 4 | AE36: =SUM(AC36:AD36) -> 0 | AJ36: 0 | AL36: =AC36 -> 0 | AM36: 4
X37: 5 | AE37: =SUM(AC37:AD37) -> 0 | AJ37: =AE37 -> 0 | AL37: =AC37 -> 0 | AM37: 5
X38: 6 | AE38: =SUM(AC38:AD38) -> 0 | AJ38: 0 | AL38: =AC38 -> 0 | AM38: 6
X39: 7 | AE39: =SUM(AC39:AD39) -> 0 | AJ39: =AE39 -> 0 | AL39: =AC39 -> 0 | AM39: 7
X40: 8 | AE40: =SUM(AC40:AD40) -> 0 | AJ40: =AE40 -> 0 | AL40: =AC40 -> 0 | AM40: 8
...

Sheet SEPT 2026
A1: 44804 | C1: RECETTE | G1: CAISSE | M1: MOUVEMENT CAISSE | P1: CAISSE MOIS PREC | Q1: PAYEMENT FOURNISSEUR CAISSE | R1: MONTANT | S1: TOTAL | T1: DATE SORTIE | Y1: FOURNISSEUR | Z1: DATE | AA1: REFERENCE | AB1: COMPTE | AC1: HTVA | AD1: TVA | AE1: MONTANT | AF1: PAIEMENT | AG1: CAISSE | AH1: DATE | AI1: ECHEANCE
A2: DATE | B2: FACTURE | C2: 6 | D2: 12 | E2: 21 | F2: TOTAL | G2: CHIFF | H2: carte | I2: cadeau0 | J2: bque | K2: liquide | L2: TOT CAIS | M2: SORTIE | N2: vers ban | O2: solde cai | P2: ='AOUT 2026'!P33 -> 268.9 | AB2: 44804
A3: 44804 | F3: =SUM(B3:E3) -> 0 | G3: =F3 -> 0 | K3: =SUM(F3-H3-J3-I3) -> 0 | L3: =SUM(F3-H3-J3-I3) -> 0 | O3: =SUM(L3-M3-N3+P2) -> 268.9 | X3: 1 | AE3: =SUM(AC3:AD3) -> 0 | AJ3: 0
A4: 44805 | F4: =SUM(B4:E4) -> 0 | G4: =F4 -> 0 | K4: =SUM(F4-H4-J4-I4) -> 0 | L4: =SUM(F4-H4-J4-I4) -> 0 | O4: =SUM(L4-M4-N4+O3+P4) -> 268.9 | X4: 2 | AE4: =SUM(AC4:AD4) -> 0 | AJ4: =AE4 -> 0
A5: 44806 | F5: =SUM(B5:E5) -> 0 | G5: =F5 -> 0 | K5: =SUM(F5-H5-J5-I5) -> 0 | L5: =SUM(F5-H5-J5-I5) -> 0 | O5: =SUM(L5-M5-N5+O4+P5) -> 268.9 | X5: 3 | AE5: =SUM(AC5:AD5) -> 0 | AJ5: 0
A6: 44807 | F6: =SUM(B6:E6) -> 0 | G6: =F6 -> 0 | K6: =SUM(F6-H6-J6-I6) -> 0 | L6: =SUM(F6-H6-J6-I6) -> 0 | O6: =SUM(L6-M6-N6+O5+P6) -> 268.9 | X6: 4 | AE6: =SUM(AC6:AD6) -> 0 | AJ6: 0
A7: 44808 | F7: =SUM(B7:E7) -> 0 | G7: =F7 -> 0 | K7: =SUM(F7-H7-J7-I7) -> 0 | L7: =SUM(F7-H7-J7-I7) -> 0 | O7: =SUM(L7-M7-N7+O6+P7) -> 268.9 | X7: 5 | AE7: =SUM(AC7:AD7) -> 0 | AJ7: 0
A8: 44809 | F8: =SUM(B8:E8) -> 0 | G8: =F8 -> 0 | K8: =SUM(F8-H8-J8-I8) -> 0 | L8: =SUM(F8-H8-J8-I8) -> 0 | O8: =SUM(L8-M8-N8+O7+P8) -> 268.9 | X8: 6 | AE8: =SUM(AC8:AD8) -> 0 | AJ8: 0
A9: 44810 | F9: =SUM(B9:E9) -> 0 | G9: =F9 -> 0 | K9: =SUM(F9-H9-J9-I9) -> 0 | L9: =SUM(F9-H9-J9-I9) -> 0 | O9: =SUM(L9-M9-N9+O8) -> 268.9 | X9: 7 | AE9: =SUM(AC9:AD9) -> 0 | AJ9: =AE9 -> 0
A10: 44811 | F10: =SUM(B10:E10) -> 0 | G10: =F10 -> 0 | K10: =SUM(F10-H10-J10-I10) -> 0 | L10: =SUM(F10-H10-J10-I10) -> 0 | O10: =SUM(L10-M10-N10+O9) -> 268.9 | X10: 8 | AE10: =SUM(AC10:AD10) -> 0 | AJ10: =AE10 -> 0
A11: 44812 | F11: =SUM(B11:E11) -> 0 | G11: =F11 -> 0 | K11: =SUM(F11-H11-J11-I11) -> 0 | L11: =SUM(F11-H11-J11-I11) -> 0 | O11: =SUM(L11-M11-N11+O10) -> 268.9 | X11: 9 | AE11: =SUM(AC11:AD11) -> 0 | AJ11: =AE11 -> 0
A12: 44813 | F12: =SUM(B12:E12) -> 0 | G12: =F12 -> 0 | K12: =SUM(F12-H12-J12-I12) -> 0 | L12: =SUM(F12-H12-J12-I12) -> 0 | O12: =SUM(L12-M12-N12+O11) -> 268.9 | X12: 10 | AE12: =SUM(AC12:AD12) -> 0 | AJ12: =AE12 -> 0
A13: 44814 | F13: =SUM(B13:E13) -> 0 | G13: =F13 -> 0 | K13: =SUM(F13-H13-J13-I13) -> 0 | L13: =SUM(F13-H13-J13-I13) -> 0 | O13: =SUM(L13-M13-N13+O12) -> 268.9 | X13: 11 | AE13: =SUM(AC13:AD13) -> 0 | AJ13: =AE13 -> 0
A14: 44815 | F14: =SUM(B14:E14) -> 0 | G14: =F14 -> 0 | K14: =SUM(F14-H14-J14-I14) -> 0 | L14: =SUM(F14-H14-J14-I14) -> 0 | O14: =SUM(L14-M14-N14+O13) -> 268.9 | X14: 12 | AE14: =SUM(AC14:AD14) -> 0 | AJ14: =AE14 -> 0
A15: 44816 | F15: =SUM(B15:E15) -> 0 | G15: =F15 -> 0 | K15: =SUM(F15-H15-J15-I15) -> 0 | L15: =SUM(F15-H15-J15-I15) -> 0 | O15: =SUM(L15-M15-N15+O14) -> 268.9 | X15: 13 | AE15: =SUM(AC15:AD15) -> 0 | AJ15: =AE15 -> 0
A16: 44817 | F16: =SUM(B16:E16) -> 0 | G16: =F16 -> 0 | K16: =SUM(F16-H16-J16-I16) -> 0 | L16: =SUM(F16-H16-J16-I16) -> 0 | O16: =SUM(L16-M16-N16+O15) -> 268.9 | X16: 14 | AE16: =SUM(AC16:AD16) -> 0 | AJ16: =AE16 -> 0
A17: 44818 | F17: =SUM(B17:E17) -> 0 | G17: =F17 -> 0 | K17: =SUM(F17-H17-J17-I17) -> 0 | L17: =SUM(F17-H17-J17-I17) -> 0 | O17: =SUM(L17-M17-N17+O16+P17) -> 268.9 | X17: 15 | AE17: =SUM(AC17:AD17) -> 0 | AJ17: =AE17 -> 0
A18: 44819 | F18: =SUM(B18:E18) -> 0 | G18: =F18 -> 0 | K18: =SUM(F18-H18-J18-I18) -> 0 | L18: =SUM(F18-H18-J18-I18) -> 0 | O18: =SUM(L18-M18-N18+O17+P18) -> 268.9 | X18: 16 | AE18: =SUM(AC18:AD18) -> 0 | AJ18: =AE18 -> 0
A19: 44820 | F19: =SUM(B19:E19) -> 0 | G19: =F19 -> 0 | K19: =SUM(F19-H19-J19-I19) -> 0 | L19: =SUM(F19-H19-J19-I19) -> 0 | O19: =SUM(L19-M19-N19+O18+P19) -> 268.9 | X19: 17 | AE19: =SUM(AC19:AD19) -> 0 | AJ19: =AE19 -> 0
A20: 44821 | F20: =SUM(B20:E20) -> 0 | G20: =F20 -> 0 | K20: =SUM(F20-H20-J20-I20) -> 0 | L20: =SUM(F20-H20-J20-I20) -> 0 | O20: =SUM(L20-M20-N20+O19+P20) -> 268.9 | X20: 18 | AE20: =SUM(AC20:AD20) -> 0 | AJ20: =AE20 -> 0
A21: 44822 | F21: =SUM(B21:E21) -> 0 | G21: =F21 -> 0 | K21: =SUM(F21-H21-J21-I21) -> 0 | L21: =SUM(F21-H21-J21-I21) -> 0 | O21: =SUM(L21-M21-N21+O20) -> 268.9 | X21: 19 | AE21: =SUM(AC21:AD21) -> 0 | AJ21: =AE21 -> 0
A22: 44823 | F22: =SUM(B22:E22) -> 0 | G22: =F22 -> 0 | K22: =SUM(F22-H22-J22-I22) -> 0 | L22: =SUM(F22-H22-J22-I22) -> 0 | O22: =SUM(L22-M22-N22+O21) -> 268.9 | X22: 20 | AE22: =SUM(AC22:AD22) -> 0 | AJ22: =AE22 -> 0
A23: 44824 | F23: =SUM(B23:E23) -> 0 | G23: =F23 -> 0 | K23: =SUM(F23-H23-J23-I23) -> 0 | L23: =SUM(F23-H23-J23-I23) -> 0 | O23: =SUM(L23-M23-N23+O22) -> 268.9 | X23: 21 | AE23: =SUM(AC23:AD23) -> 0 | AJ23: =AE23 -> 0
A24: 44825 | F24: =SUM(B24:E24) -> 0 | G24: =F24 -> 0 | K24: =SUM(F24-H24-J24-I24) -> 0 | L24: =SUM(F24-H24-J24-I24) -> 0 | O24: =SUM(L24-M24-N24+O23+P24) -> 268.9 | X24: 22 | AE24: =SUM(AC24:AD24) -> 0 | AJ24: =AE24 -> 0
A25: 44826 | F25: =SUM(B25:E25) -> 0 | G25: =F25 -> 0 | K25: =SUM(F25-H25-J25-I25) -> 0 | L25: =SUM(F25-H25-J25-I25) -> 0 | O25: =SUM(L25-M25-N25+O24) -> 268.9 | X25: 26 | AE25: =SUM(AC25:AD25) -> 0 | AJ25: =AE25 -> 0
A26: 44827 | F26: =SUM(B26:E26) -> 0 | G26: =F26 -> 0 | K26: =SUM(F26-H26-J26-I26) -> 0 | L26: =SUM(F26-H26-J26-I26) -> 0 | O26: =SUM(L26-M26-N26+O25) -> 268.9 | X26: 27 | AE26: =SUM(AC26:AD26) -> 0 | AJ26: =AE26 -> 0
A27: 44828 | F27: =SUM(B27:E27) -> 0 | G27: =F27 -> 0 | K27: =SUM(F27-H27-J27-I27) -> 0 | L27: =SUM(F27-H27-J27-I27) -> 0 | O27: =SUM(L27-M27-N27+O26) -> 268.9 | X27: 28 | AE27: =SUM(AC27:AD27) -> 0 | AJ27: =AE27 -> 0
A28: 44829 | F28: =SUM(B28:E28) -> 0 | G28: =F28 -> 0 | K28: =SUM(F28-H28-J28-I28) -> 0 | L28: =SUM(F28-H28-J28-I28) -> 0 | O28: =SUM(L28-M28-N28+O27+P28) -> 268.9 | X28: 29 | AE28: =SUM(AC28:AD28) -> 0 | AJ28: =AE28 -> 0
A29: 44830 | F29: =SUM(B29:E29) -> 0 | G29: =F29 -> 0 | K29: =SUM(F29-H29-J29-I29) -> 0 | L29: =SUM(F29-H29-J29-I29) -> 0 | O29: =SUM(L29-M29-N29+O28) -> 268.9 | X29: 30 | AE29: =SUM(AC29:AD29) -> 0 | AJ29: =AE29 -> 0
A30: 44831 | F30: =SUM(B30:E30) -> 0 | G30: =F30 -> 0 | K30: =SUM(F30-H30-J30-I30) -> 0 | L30: =SUM(F30-H30-J30-I30) -> 0 | O30: =SUM(L30-M30-N30+O29+P30) -> 268.9 | AC30: TVA | AD30: =SUM(AD3:AD29) -> 0
A31: 44832 | F31: =SUM(B31:E31) -> 0 | G31: =F31 -> 0 | K31: =SUM(F31-H31-J31-I31) -> 0 | L31: =SUM(F31-H31-J31-I31) -> 0 | O31: =SUM(L31-M31-N31+O30) -> 268.9 | P31: SOLDE CAISSE
A32: 44833 | F32: =SUM(B32:E32) -> 0 | G32: =F32 -> 0 | K32: =SUM(F32-H32-J32-I32) -> 0 | L32: =SUM(F32-H32-J32-I32) -> 0 | O32: =SUM(L32-M32-N32+O31) -> 268.9 | P32: DU MOIS | AA32: MARGE | AL32: calcul de marge
F33: =SUM(B33:E33) -> 0 | G33: =F33 -> 0 | K33: =SUM(F33-H33-J33-I33) -> 0 | L33: =SUM(F33-H33-J33-I33) -> 0 | O33: =SUM(L33-M33-N33+O32) -> 268.9 | P33: =SUM(O33) -> 268.9 | X33: 1 | AE33: =SUM(AC33:AD33) -> 0 | AJ33: 0 | AL33: =AC33 -> 0 | AM33: 1
B34: =SUM(B5:B33) -> 0 | C34: =SUM(C3:C33) -> 0 | D34: =SUM(D3:D33) -> 0 | E34: =SUM(E3:E33) -> 0 | F34: =SUM(F3:F33) -> 0 | H34: =SUM(H3:H33) -> 0 | J34: =SUM(J3:J33) -> 0 | K34: =SUM(K3:K33) -> 0 | L34: =SUM(L3:L33) -> 0 | M34: =SUM(M3:M33) -> 0 | N34: =SUM(N3:N33) -> 0 | X34: 2 | AE34: =SUM(AC34:AD34) -> 0 | AJ34: =AE34 -> 0 | AL34: =AC34 -> 0 | AM34: 2
A35: HTVA | B35: =SUM(B3:B33) -> 0 | C35: =SUM(C34/1.06) -> 0 | D35: =SUM(D34/1.12) -> 0 | E35: =SUM(E34/1.21) -> 0 | F35: =SUM(B35:E35) -> 0 | G35: =SUM(G34:G34) -> 0 | L35: TOTAL SORTIE | N35: =SUM(M34:N34) -> 0 | X35: 3 | AE35: =SUM(AC35:AD35) -> 0 | AJ35: =AE35 -> 0 | AL35: =AC35 -> 0 | AM35: 3
A36: TVA | C36: =SUM(C34-C35) -> 0 | D36: =SUM(D34-D35) -> 0 | E36: =SUM(E34-E35) -> 0 | F36: =SUM(C36:E36) -> 0 | X36: 4 | AE36: =SUM(AC36:AD36) -> 0 | AJ36: 0 | AL36: =AC36 -> 0 | AM36: 4
X37: 5 | AE37: =SUM(AC37:AD37) -> 0 | AJ37: =AE37 -> 0 | AL37: =AC37 -> 0 | AM37: 5
X38: 6 | AE38: =SUM(AC38:AD38) -> 0 | AJ38: 0 | AL38: =AC38 -> 0 | AM38: 6
X39: 7 | AE39: =SUM(AC39:AD39) -> 0 | AJ39: =AE39 -> 0 | AL39: =AC39 -> 0 | AM39: 7
X40: 8 | AE40: =SUM(AC40:AD40) -> 0 | AJ40: =AE40 -> 0 | AL40: =AC40 -> 0 | AM40: 8
...

Sheet AOUT 2026
A1: 44773 | C1: RECETTE | G1: CAISSE | M1: MOUVEMENT CAISSE | P1: CAISSE MOIS PREC | Q1: PAYEMENT FOURNISSEUR CAISSE | R1: MONTANT | S1: TOTAL | T1: DATE SORTIE | Y1: FOURNISSEUR | Z1: DATE | AA1: REFERENCE | AB1: COMPTE | AC1: HTVA | AD1: TVA | AE1: MONTANT | AF1: PAIEMENT | AG1: CAISSE | AH1: DATE | AI1: ECHEANCE
A2: DATE | B2: FACTURE | C2: 6 | D2: 12 | E2: 21 | F2: TOTAL | G2: CHIFF | H2: carte | I2: cadeau0 | J2: bque | K2: liquide | L2: TOT CAIS | M2: SORTIE | N2: vers ban | O2: solde cai | P2: ='JUILLET 2026'!P33 -> 268.9 | AB2: 44773
A3: 44773 | F3: =SUM(B3:E3) -> 0 | G3: =F3 -> 0 | K3: =SUM(F3-H3-J3-I3) -> 0 | L3: =SUM(F3-H3-J3-I3) -> 0 | O3: =SUM(L3-M3-N3+P2) -> 268.9 | X3: 1 | AE3: =SUM(AC3:AD3) -> 0 | AJ3: 0
A4: 44774 | F4: =SUM(B4:E4) -> 0 | G4: =F4 -> 0 | K4: =SUM(F4-H4-J4-I4) -> 0 | L4: =SUM(F4-H4-J4-I4) -> 0 | O4: =SUM(L4-M4-N4+O3+P4) -> 268.9 | X4: 2 | AE4: =SUM(AC4:AD4) -> 0 | AJ4: =AE4 -> 0
A5: 44775 | F5: =SUM(B5:E5) -> 0 | G5: =F5 -> 0 | K5: =SUM(F5-H5-J5-I5) -> 0 | L5: =SUM(F5-H5-J5-I5) -> 0 | O5: =SUM(L5-M5-N5+O4+P5) -> 268.9 | X5: 3 | AE5: =SUM(AC5:AD5) -> 0 | AJ5: 0
A6: 44776 | F6: =SUM(B6:E6) -> 0 | G6: =F6 -> 0 | K6: =SUM(F6-H6-J6-I6) -> 0 | L6: =SUM(F6-H6-J6-I6) -> 0 | O6: =SUM(L6-M6-N6+O5+P6) -> 268.9 | X6: 4 | AE6: =SUM(AC6:AD6) -> 0 | AJ6: 0
A7: 44777 | F7: =SUM(B7:E7) -> 0 | G7: =F7 -> 0 | K7: =SUM(F7-H7-J7-I7) -> 0 | L7: =SUM(F7-H7-J7-I7) -> 0 | O7: =SUM(L7-M7-N7+O6+P7) -> 268.9 | X7: 5 | AE7: =SUM(AC7:AD7) -> 0 | AJ7: 0
A8: 44778 | F8: =SUM(B8:E8) -> 0 | G8: =F8 -> 0 | K8: =SUM(F8-H8-J8-I8) -> 0 | L8: =SUM(F8-H8-J8-I8) -> 0 | O8: =SUM(L8-M8-N8+O7+P8) -> 268.9 | X8: 6 | AE8: =SUM(AC8:AD8) -> 0 | AJ8: 0
A9: 44779 | F9: =SUM(B9:E9) -> 0 | G9: =F9 -> 0 | K9: =SUM(F9-H9-J9-I9) -> 0 | L9: =SUM(F9-H9-J9-I9) -> 0 | O9: =SUM(L9-M9-N9+O8) -> 268.9 | X9: 7 | AE9: =SUM(AC9:AD9) -> 0 | AJ9: =AE9 -> 0
A10: 44780 | F10: =SUM(B10:E10) -> 0 | G10: =F10 -> 0 | K10: =SUM(F10-H10-J10-I10) -> 0 | L10: =SUM(F10-H10-J10-I10) -> 0 | O10: =SUM(L10-M10-N10+O9) -> 268.9 | X10: 8 | AE10: =SUM(AC10:AD10) -> 0 | AJ10: =AE10 -> 0
A11: 44781 | F11: =SUM(B11:E11) -> 0 | G11: =F11 -> 0 | K11: =SUM(F11-H11-J11-I11) -> 0 | L11: =SUM(F11-H11-J11-I11) -> 0 | O11: =SUM(L11-M11-N11+O10) -> 268.9 | X11: 9 | AE11: =SUM(AC11:AD11) -> 0 | AJ11: =AE11 -> 0
A12: 44782 | F12: =SUM(B12:E12) -> 0 | G12: =F12 -> 0 | K12: =SUM(F12-H12-J12-I12) -> 0 | L12: =SUM(F12-H12-J12-I12) -> 0 | O12: =SUM(L12-M12-N12+O11) -> 268.9 | X12: 10 | AE12: =SUM(AC12:AD12) -> 0 | AJ12: =AE12 -> 0
A13: 44783 | F13: =SUM(B13:E13) -> 0 | G13: =F13 -> 0 | K13: =SUM(F13-H13-J13-I13) -> 0 | L13: =SUM(F13-H13-J13-I13) -> 0 | O13: =SUM(L13-M13-N13+O12) -> 268.9 | X13: 11 | AE13: =SUM(AC13:AD13) -> 0 | AJ13: =AE13 -> 0
A14: 44784 | F14: =SUM(B14:E14) -> 0 | G14: =F14 -> 0 | K14: =SUM(F14-H14-J14-I14) -> 0 | L14: =SUM(F14-H14-J14-I14) -> 0 | O14: =SUM(L14-M14-N14+O13) -> 268.9 | X14: 12 | AE14: =SUM(AC14:AD14) -> 0 | AJ14: =AE14 -> 0
A15: 44785 | F15: =SUM(B15:E15) -> 0 | G15: =F15 -> 0 | K15: =SUM(F15-H15-J15-I15) -> 0 | L15: =SUM(F15-H15-J15-I15) -> 0 | O15: =SUM(L15-M15-N15+O14) -> 268.9 | X15: 13 | AE15: =SUM(AC15:AD15) -> 0 | AJ15: =AE15 -> 0
A16: 44786 | F16: =SUM(B16:E16) -> 0 | G16: =F16 -> 0 | K16: =SUM(F16-H16-J16-I16) -> 0 | L16: =SUM(F16-H16-J16-I16) -> 0 | O16: =SUM(L16-M16-N16+O15) -> 268.9 | X16: 14 | AE16: =SUM(AC16:AD16) -> 0 | AJ16: =AE16 -> 0
A17: 44787 | F17: =SUM(B17:E17) -> 0 | G17: =F17 -> 0 | K17: =SUM(F17-H17-J17-I17) -> 0 | L17: =SUM(F17-H17-J17-I17) -> 0 | O17: =SUM(L17-M17-N17+O16+P17) -> 268.9 | X17: 15 | AE17: =SUM(AC17:AD17) -> 0 | AJ17: =AE17 -> 0
A18: 44788 | F18: =SUM(B18:E18) -> 0 | G18: =F18 -> 0 | K18: =SUM(F18-H18-J18-I18) -> 0 | L18: =SUM(F18-H18-J18-I18) -> 0 | O18: =SUM(L18-M18-N18+O17+P18) -> 268.9 | X18: 16 | AE18: =SUM(AC18:AD18) -> 0 | AJ18: =AE18 -> 0
A19: 44789 | F19: =SUM(B19:E19) -> 0 | G19: =F19 -> 0 | K19: =SUM(F19-H19-J19-I19) -> 0 | L19: =SUM(F19-H19-J19-I19) -> 0 | O19: =SUM(L19-M19-N19+O18+P19) -> 268.9 | X19: 17 | AE19: =SUM(AC19:AD19) -> 0 | AJ19: =AE19 -> 0
A20: 44790 | F20: =SUM(B20:E20) -> 0 | G20: =F20 -> 0 | K20: =SUM(F20-H20-J20-I20) -> 0 | L20: =SUM(F20-H20-J20-I20) -> 0 | O20: =SUM(L20-M20-N20+O19+P20) -> 268.9 | X20: 18 | AE20: =SUM(AC20:AD20) -> 0 | AJ20: =AE20 -> 0
A21: 44791 | F21: =SUM(B21:E21) -> 0 | G21: =F21 -> 0 | K21: =SUM(F21-H21-J21-I21) -> 0 | L21: =SUM(F21-H21-J21-I21) -> 0 | O21: =SUM(L21-M21-N21+O20) -> 268.9 | X21: 19 | AE21: =SUM(AC21:AD21) -> 0 | AJ21: =AE21 -> 0
A22: 44792 | F22: =SUM(B22:E22) -> 0 | G22: =F22 -> 0 | K22: =SUM(F22-H22-J22-I22) -> 0 | L22: =SUM(F22-H22-J22-I22) -> 0 | O22: =SUM(L22-M22-N22+O21) -> 268.9 | X22: 20 | AE22: =SUM(AC22:AD22) -> 0 | AJ22: =AE22 -> 0
A23: 44793 | F23: =SUM(B23:E23) -> 0 | G23: =F23 -> 0 | K23: =SUM(F23-H23-J23-I23) -> 0 | L23: =SUM(F23-H23-J23-I23) -> 0 | O23: =SUM(L23-M23-N23+O22) -> 268.9 | X23: 21 | AE23: =SUM(AC23:AD23) -> 0 | AJ23: =AE23 -> 0
A24: 44794 | F24: =SUM(B24:E24) -> 0 | G24: =F24 -> 0 | K24: =SUM(F24-H24-J24-I24) -> 0 | L24: =SUM(F24-H24-J24-I24) -> 0 | O24: =SUM(L24-M24-N24+O23+P24) -> 268.9 | X24: 22 | AE24: =SUM(AC24:AD24) -> 0 | AJ24: =AE24 -> 0
A25: 44795 | F25: =SUM(B25:E25) -> 0 | G25: =F25 -> 0 | K25: =SUM(F25-H25-J25-I25) -> 0 | L25: =SUM(F25-H25-J25-I25) -> 0 | O25: =SUM(L25-M25-N25+O24) -> 268.9 | X25: 26 | AE25: =SUM(AC25:AD25) -> 0 | AJ25: =AE25 -> 0
A26: 44796 | F26: =SUM(B26:E26) -> 0 | G26: =F26 -> 0 | K26: =SUM(F26-H26-J26-I26) -> 0 | L26: =SUM(F26-H26-J26-I26) -> 0 | O26: =SUM(L26-M26-N26+O25) -> 268.9 | X26: 27 | AE26: =SUM(AC26:AD26) -> 0 | AJ26: =AE26 -> 0
A27: 44797 | F27: =SUM(B27:E27) -> 0 | G27: =F27 -> 0 | K27: =SUM(F27-H27-J27-I27) -> 0 | L27: =SUM(F27-H27-J27-I27) -> 0 | O27: =SUM(L27-M27-N27+O26) -> 268.9 | X27: 28 | AE27: =SUM(AC27:AD27) -> 0 | AJ27: =AE27 -> 0
A28: 44798 | F28: =SUM(B28:E28) -> 0 | G28: =F28 -> 0 | K28: =SUM(F28-H28-J28-I28) -> 0 | L28: =SUM(F28-H28-J28-I28) -> 0 | O28: =SUM(L28-M28-N28+O27+P28) -> 268.9 | X28: 29 | AE28: =SUM(AC28:AD28) -> 0 | AJ28: =AE28 -> 0
A29: 44799 | F29: =SUM(B29:E29) -> 0 | G29: =F29 -> 0 | K29: =SUM(F29-H29-J29-I29) -> 0 | L29: =SUM(F29-H29-J29-I29) -> 0 | O29: =SUM(L29-M29-N29+O28) -> 268.9 | X29: 30 | AE29: =SUM(AC29:AD29) -> 0 | AJ29: =AE29 -> 0
A30: 44800 | F30: =SUM(B30:E30) -> 0 | G30: =F30 -> 0 | K30: =SUM(F30-H30-J30-I30) -> 0 | L30: =SUM(F30-H30-J30-I30) -> 0 | O30: =SUM(L30-M30-N30+O29+P30) -> 268.9 | AC30: TVA | AD30: =SUM(AD3:AD29) -> 0
A31: 44801 | F31: =SUM(B31:E31) -> 0 | G31: =F31 -> 0 | K31: =SUM(F31-H31-J31-I31) -> 0 | L31: =SUM(F31-H31-J31-I31) -> 0 | O31: =SUM(L31-M31-N31+O30) -> 268.9 | P31: SOLDE CAISSE
A32: 44802 | F32: =SUM(B32:E32) -> 0 | G32: =F32 -> 0 | K32: =SUM(F32-H32-J32-I32) -> 0 | L32: =SUM(F32-H32-J32-I32) -> 0 | O32: =SUM(L32-M32-N32+O31) -> 268.9 | P32: DU MOIS | AA32: MARGE | AL32: calcul de marge
A33: 44803 | F33: =SUM(B33:E33) -> 0 | G33: =F33 -> 0 | K33: =SUM(F33-H33-J33-I33) -> 0 | L33: =SUM(F33-H33-J33-I33) -> 0 | O33: =SUM(L33-M33-N33+O32) -> 268.9 | P33: =SUM(O33) -> 268.9 | X33: 1 | AE33: =SUM(AC33:AD33) -> 0 | AJ33: 0 | AL33: =AC33 -> 0 | AM33: 1
B34: =SUM(B5:B33) -> 0 | C34: =SUM(C3:C33) -> 0 | D34: =SUM(D3:D33) -> 0 | E34: =SUM(E3:E33) -> 0 | F34: =SUM(F3:F33) -> 0 | H34: =SUM(H3:H33) -> 0 | J34: =SUM(J3:J33) -> 0 | K34: =SUM(K3:K33) -> 0 | L34: =SUM(L3:L33) -> 0 | M34: =SUM(M3:M33) -> 0 | N34: =SUM(N3:N33) -> 0 | X34: 2 | AE34: =SUM(AC34:AD34) -> 0 | AJ34: =AE34 -> 0 | AL34: =AC34 -> 0 | AM34: 2
A35: HTVA | B35: =SUM(B3:B33) -> 0 | C35: =SUM(C34/1.06) -> 0 | D35: =SUM(D34/1.12) -> 0 | E35: =SUM(E34/1.21) -> 0 | F35: =SUM(B35:E35) -> 0 | G35: =SUM(G34:G34) -> 0 | L35: TOTAL SORTIE | N35: =SUM(M34:N34) -> 0 | X35: 3 | AE35: =SUM(AC35:AD35) -> 0 | AJ35: =AE35 -> 0 | AL35: =AC35 -> 0 | AM35: 3
A36: TVA | C36: =SUM(C34-C35) -> 0 | D36: =SUM(D34-D35) -> 0 | E36: =SUM(E34-E35) -> 0 | F36: =SUM(C36:E36) -> 0 | X36: 4 | AE36: =SUM(AC36:AD36) -> 0 | AJ36: 0 | AL36: =AC36 -> 0 | AM36: 4
X37: 5 | AE37: =SUM(AC37:AD37) -> 0 | AJ37: =AE37 -> 0 | AL37: =AC37 -> 0 | AM37: 5
X38: 6 | AE38: =SUM(AC38:AD38) -> 0 | AJ38: 0 | AL38: =AC38 -> 0 | AM38: 6
X39: 7 | AE39: =SUM(AC39:AD39) -> 0 | AJ39: =AE39 -> 0 | AL39: =AC39 -> 0 | AM39: 7
X40: 8 | AE40: =SUM(AC40:AD40) -> 0 | AJ40: =AE40 -> 0 | AL40: =AC40 -> 0 | AM40: 8
...

Sheet JUILLET 2026
A1: 44742 | C1: RECETTE | G1: CAISSE | M1: MOUVEMENT CAISSE | P1: CAISSE MOIS PREC | Q1: PAYEMENT FOURNISSEUR CAISSE | R1: MONTANT | S1: TOTAL | T1: DATE SORTIE | Y1: FOURNISSEUR | Z1: DATE | AA1: REFERENCE | AB1: COMPTE | AC1: HTVA | AD1: TVA | AE1: MONTANT | AF1: PAIEMENT | AG1: CAISSE | AH1: DATE | AI1: ECHEANCE
A2: DATE | B2: FACTURE | C2: 6 | D2: 12 | E2: 21 | F2: TOTAL | G2: CHIFF | H2: carte | I2: cadeau0 | J2: bque | K2: liquide | L2: TOT CAIS | M2: SORTIE | N2: vers ban | O2: solde cai | P2: ='JUIN 2026'!P33 -> 268.9 | AB2: 44742
A3: 44742 | F3: =SUM(B3:E3) -> 0 | G3: =F3 -> 0 | K3: =SUM(F3-H3-J3-I3) -> 0 | L3: =SUM(F3-H3-J3-I3) -> 0 | O3: =SUM(L3-M3-N3+P2) -> 268.9 | X3: 1 | AE3: =SUM(AC3:AD3) -> 0 | AJ3: 0
A4: 44743 | F4: =SUM(B4:E4) -> 0 | G4: =F4 -> 0 | K4: =SUM(F4-H4-J4-I4) -> 0 | L4: =SUM(F4-H4-J4-I4) -> 0 | O4: =SUM(L4-M4-N4+O3+P4) -> 268.9 | X4: 2 | AE4: =SUM(AC4:AD4) -> 0 | AJ4: =AE4 -> 0
A5: 44744 | F5: =SUM(B5:E5) -> 0 | G5: =F5 -> 0 | K5: =SUM(F5-H5-J5-I5) -> 0 | L5: =SUM(F5-H5-J5-I5) -> 0 | O5: =SUM(L5-M5-N5+O4+P5) -> 268.9 | X5: 3 | AE5: =SUM(AC5:AD5) -> 0 | AJ5: 0
A6: 44745 | F6: =SUM(B6:E6) -> 0 | G6: =F6 -> 0 | K6: =SUM(F6-H6-J6-I6) -> 0 | L6: =SUM(F6-H6-J6-I6) -> 0 | O6: =SUM(L6-M6-N6+O5+P6) -> 268.9 | X6: 4 | AE6: =SUM(AC6:AD6) -> 0 | AJ6: 0
A7: 44746 | F7: =SUM(B7:E7) -> 0 | G7: =F7 -> 0 | K7: =SUM(F7-H7-J7-I7) -> 0 | L7: =SUM(F7-H7-J7-I7) -> 0 | O7: =SUM(L7-M7-N7+O6+P7) -> 268.9 | X7: 5 | AE7: =SUM(AC7:AD7) -> 0 | AJ7: 0
A8: 44747 | F8: =SUM(B8:E8) -> 0 | G8: =F8 -> 0 | K8: =SUM(F8-H8-J8-I8) -> 0 | L8: =SUM(F8-H8-J8-I8) -> 0 | O8: =SUM(L8-M8-N8+O7+P8) -> 268.9 | X8: 6 | AE8: =SUM(AC8:AD8) -> 0 | AJ8: 0
A9: 44748 | F9: =SUM(B9:E9) -> 0 | G9: =F9 -> 0 | K9: =SUM(F9-H9-J9-I9) -> 0 | L9: =SUM(F9-H9-J9-I9) -> 0 | O9: =SUM(L9-M9-N9+O8) -> 268.9 | X9: 7 | AE9: =SUM(AC9:AD9) -> 0 | AJ9: =AE9 -> 0
A10: 44749 | F10: =SUM(B10:E10) -> 0 | G10: =F10 -> 0 | K10: =SUM(F10-H10-J10-I10) -> 0 | L10: =SUM(F10-H10-J10-I10) -> 0 | O10: =SUM(L10-M10-N10+O9) -> 268.9 | X10: 8 | AE10: =SUM(AC10:AD10) -> 0 | AJ10: =AE10 -> 0
A11: 44750 | F11: =SUM(B11:E11) -> 0 | G11: =F11 -> 0 | K11: =SUM(F11-H11-J11-I11) -> 0 | L11: =SUM(F11-H11-J11-I11) -> 0 | O11: =SUM(L11-M11-N11+O10) -> 268.9 | X11: 9 | AE11: =SUM(AC11:AD11) -> 0 | AJ11: =AE11 -> 0
A12: 44751 | F12: =SUM(B12:E12) -> 0 | G12: =F12 -> 0 | K12: =SUM(F12-H12-J12-I12) -> 0 | L12: =SUM(F12-H12-J12-I12) -> 0 | O12: =SUM(L12-M12-N12+O11) -> 268.9 | X12: 10 | AE12: =SUM(AC12:AD12) -> 0 | AJ12: =AE12 -> 0
A13: 44752 | F13: =SUM(B13:E13) -> 0 | G13: =F13 -> 0 | K13: =SUM(F13-H13-J13-I13) -> 0 | L13: =SUM(F13-H13-J13-I13) -> 0 | O13: =SUM(L13-M13-N13+O12) -> 268.9 | X13: 11 | AE13: =SUM(AC13:AD13) -> 0 | AJ13: =AE13 -> 0
A14: 44753 | F14: =SUM(B14:E14) -> 0 | G14: =F14 -> 0 | K14: =SUM(F14-H14-J14-I14) -> 0 | L14: =SUM(F14-H14-J14-I14) -> 0 | O14: =SUM(L14-M14-N14+O13) -> 268.9 | X14: 12 | AE14: =SUM(AC14:AD14) -> 0 | AJ14: =AE14 -> 0
A15: 44754 | F15: =SUM(B15:E15) -> 0 | G15: =F15 -> 0 | K15: =SUM(F15-H15-J15-I15) -> 0 | L15: =SUM(F15-H15-J15-I15) -> 0 | O15: =SUM(L15-M15-N15+O14) -> 268.9 | X15: 13 | AE15: =SUM(AC15:AD15) -> 0 | AJ15: =AE15 -> 0
A16: 44755 | F16: =SUM(B16:E16) -> 0 | G16: =F16 -> 0 | K16: =SUM(F16-H16-J16-I16) -> 0 | L16: =SUM(F16-H16-J16-I16) -> 0 | O16: =SUM(L16-M16-N16+O15) -> 268.9 | X16: 14 | AE16: =SUM(AC16:AD16) -> 0 | AJ16: =AE16 -> 0
A17: 44756 | F17: =SUM(B17:E17) -> 0 | G17: =F17 -> 0 | K17: =SUM(F17-H17-J17-I17) -> 0 | L17: =SUM(F17-H17-J17-I17) -> 0 | O17: =SUM(L17-M17-N17+O16+P17) -> 268.9 | X17: 15 | AE17: =SUM(AC17:AD17) -> 0 | AJ17: =AE17 -> 0
A18: 44757 | F18: =SUM(B18:E18) -> 0 | G18: =F18 -> 0 | K18: =SUM(F18-H18-J18-I18) -> 0 | L18: =SUM(F18-H18-J18-I18) -> 0 | O18: =SUM(L18-M18-N18+O17+P18) -> 268.9 | X18: 16 | AE18: =SUM(AC18:AD18) -> 0 | AJ18: =AE18 -> 0
A19: 44758 | F19: =SUM(B19:E19) -> 0 | G19: =F19 -> 0 | K19: =SUM(F19-H19-J19-I19) -> 0 | L19: =SUM(F19-H19-J19-I19) -> 0 | O19: =SUM(L19-M19-N19+O18+P19) -> 268.9 | X19: 17 | AE19: =SUM(AC19:AD19) -> 0 | AJ19: =AE19 -> 0
A20: 44759 | F20: =SUM(B20:E20) -> 0 | G20: =F20 -> 0 | K20: =SUM(F20-H20-J20-I20) -> 0 | L20: =SUM(F20-H20-J20-I20) -> 0 | O20: =SUM(L20-M20-N20+O19+P20) -> 268.9 | X20: 18 | AE20: =SUM(AC20:AD20) -> 0 | AJ20: =AE20 -> 0
A21: 44760 | F21: =SUM(B21:E21) -> 0 | G21: =F21 -> 0 | K21: =SUM(F21-H21-J21-I21) -> 0 | L21: =SUM(F21-H21-J21-I21) -> 0 | O21: =SUM(L21-M21-N21+O20) -> 268.9 | X21: 19 | AE21: =SUM(AC21:AD21) -> 0 | AJ21: =AE21 -> 0
A22: 44761 | F22: =SUM(B22:E22) -> 0 | G22: =F22 -> 0 | K22: =SUM(F22-H22-J22-I22) -> 0 | L22: =SUM(F22-H22-J22-I22) -> 0 | O22: =SUM(L22-M22-N22+O21) -> 268.9 | X22: 20 | AE22: =SUM(AC22:AD22) -> 0 | AJ22: =AE22 -> 0
A23: 44762 | F23: =SUM(B23:E23) -> 0 | G23: =F23 -> 0 | K23: =SUM(F23-H23-J23-I23) -> 0 | L23: =SUM(F23-H23-J23-I23) -> 0 | O23: =SUM(L23-M23-N23+O22) -> 268.9 | X23: 21 | AE23: =SUM(AC23:AD23) -> 0 | AJ23: =AE23 -> 0
A24: 44763 | F24: =SUM(B24:E24) -> 0 | G24: =F24 -> 0 | K24: =SUM(F24-H24-J24-I24) -> 0 | L24: =SUM(F24-H24-J24-I24) -> 0 | O24: =SUM(L24-M24-N24+O23+P24) -> 268.9 | X24: 22 | AE24: =SUM(AC24:AD24) -> 0 | AJ24: =AE24 -> 0
A25: 44764 | F25: =SUM(B25:E25) -> 0 | G25: =F25 -> 0 | K25: =SUM(F25-H25-J25-I25) -> 0 | L25: =SUM(F25-H25-J25-I25) -> 0 | O25: =SUM(L25-M25-N25+O24) -> 268.9 | X25: 26 | AE25: =SUM(AC25:AD25) -> 0 | AJ25: =AE25 -> 0
A26: 44765 | F26: =SUM(B26:E26) -> 0 | G26: =F26 -> 0 | K26: =SUM(F26-H26-J26-I26) -> 0 | L26: =SUM(F26-H26-J26-I26) -> 0 | O26: =SUM(L26-M26-N26+O25) -> 268.9 | X26: 27 | AE26: =SUM(AC26:AD26) -> 0 | AJ26: =AE26 -> 0
A27: 44766 | F27: =SUM(B27:E27) -> 0 | G27: =F27 -> 0 | K27: =SUM(F27-H27-J27-I27) -> 0 | L27: =SUM(F27-H27-J27-I27) -> 0 | O27: =SUM(L27-M27-N27+O26) -> 268.9 | X27: 28 | AE27: =SUM(AC27:AD27) -> 0 | AJ27: =AE27 -> 0
A28: 44767 | F28: =SUM(B28:E28) -> 0 | G28: =F28 -> 0 | K28: =SUM(F28-H28-J28-I28) -> 0 | L28: =SUM(F28-H28-J28-I28) -> 0 | O28: =SUM(L28-M28-N28+O27+P28) -> 268.9 | X28: 29 | AE28: =SUM(AC28:AD28) -> 0 | AJ28: =AE28 -> 0
A29: 44768 | F29: =SUM(B29:E29) -> 0 | G29: =F29 -> 0 | K29: =SUM(F29-H29-J29-I29) -> 0 | L29: =SUM(F29-H29-J29-I29) -> 0 | O29: =SUM(L29-M29-N29+O28) -> 268.9 | X29: 30 | AE29: =SUM(AC29:AD29) -> 0 | AJ29: =AE29 -> 0
A30: 44769 | F30: =SUM(B30:E30) -> 0 | G30: =F30 -> 0 | K30: =SUM(F30-H30-J30-I30) -> 0 | L30: =SUM(F30-H30-J30-I30) -> 0 | O30: =SUM(L30-M30-N30+O29+P30) -> 268.9 | AC30: TVA | AD30: =SUM(AD3:AD29) -> 0
A31: 44770 | F31: =SUM(B31:E31) -> 0 | G31: =F31 -> 0 | K31: =SUM(F31-H31-J31-I31) -> 0 | L31: =SUM(F31-H31-J31-I31) -> 0 | O31: =SUM(L31-M31-N31+O30) -> 268.9 | P31: SOLDE CAISSE
A32: 44771 | F32: =SUM(B32:E32) -> 0 | G32: =F32 -> 0 | K32: =SUM(F32-H32-J32-I32) -> 0 | L32: =SUM(F32-H32-J32-I32) -> 0 | O32: =SUM(L32-M32-N32+O31) -> 268.9 | P32: DU MOIS | AA32: MARGE | AL32: calcul de marge
A33: 44772 | F33: =SUM(B33:E33) -> 0 | G33: =F33 -> 0 | K33: =SUM(F33-H33-J33-I33) -> 0 | L33: =SUM(F33-H33-J33-I33) -> 0 | O33: =SUM(L33-M33-N33+O32) -> 268.9 | P33: =SUM(O33) -> 268.9 | X33: 1 | AE33: =SUM(AC33:AD33) -> 0 | AJ33: 0 | AL33: =AC33 -> 0 | AM33: 1
B34: =SUM(B5:B33) -> 0 | C34: =SUM(C3:C33) -> 0 | D34: =SUM(D3:D33) -> 0 | E34: =SUM(E3:E33) -> 0 | F34: =SUM(F3:F33) -> 0 | H34: =SUM(H3:H33) -> 0 | J34: =SUM(J3:J33) -> 0 | K34: =SUM(K3:K33) -> 0 | L34: =SUM(L3:L33) -> 0 | M34: =SUM(M3:M33) -> 0 | N34: =SUM(N3:N33) -> 0 | X34: 2 | AE34: =SUM(AC34:AD34) -> 0 | AJ34: =AE34 -> 0 | AL34: =AC34 -> 0 | AM34: 2
A35: HTVA | B35: =SUM(B3:B33) -> 0 | C35: =SUM(C34/1.06) -> 0 | D35: =SUM(D34/1.12) -> 0 | E35: =SUM(E34/1.21) -> 0 | F35: =SUM(B35:E35) -> 0 | G35: =SUM(G34:G34) -> 0 | L35: TOTAL SORTIE | N35: =SUM(M34:N34) -> 0 | X35: 3 | AE35: =SUM(AC35:AD35) -> 0 | AJ35: =AE35 -> 0 | AL35: =AC35 -> 0 | AM35: 3
A36: TVA | C36: =SUM(C34-C35) -> 0 | D36: =SUM(D34-D35) -> 0 | E36: =SUM(E34-E35) -> 0 | F36: =SUM(C36:E36) -> 0 | X36: 4 | AE36: =SUM(AC36:AD36) -> 0 | AJ36: 0 | AL36: =AC36 -> 0 | AM36: 4
X37: 5 | AE37: =SUM(AC37:AD37) -> 0 | AJ37: =AE37 -> 0 | AL37: =AC37 -> 0 | AM37: 5
X38: 6 | AE38: =SUM(AC38:AD38) -> 0 | AJ38: 0 | AL38: =AC38 -> 0 | AM38: 6
X39: 7 | AE39: =SUM(AC39:AD39) -> 0 | AJ39: =AE39 -> 0 | AL39: =AC39 -> 0 | AM39: 7
X40: 8 | AE40: =SUM(AC40:AD40) -> 0 | AJ40: =AE40 -> 0 | AL40: =AC40 -> 0 | AM40: 8
...

Sheet JUIN 2026
A1: 44712 | C1: RECETTE | G1: CAISSE | M1: MOUVEMENT CAISSE | P1: CAISSE MOIS PREC | Q1: PAYEMENT FOURNISSEUR CAISSE | R1: MONTANT | S1: TOTAL | T1: DATE SORTIE | Y1: FOURNISSEUR | Z1: DATE | AA1: REFERENCE | AB1: COMPTE | AC1: HTVA | AD1: TVA | AE1: MONTANT | AF1: PAIEMENT | AG1: CAISSE | AH1: DATE | AI1: ECHEANCE
A2: DATE | B2: FACTURE | C2: 6 | D2: 12 | E2: 21 | F2: TOTAL | G2: CHIFF | H2: carte | I2: cadeau0 | J2: bque | K2: liquide | L2: TOT CAIS | M2: SORTIE | N2: vers ban | O2: solde cai | P2: ='MAI 2026'!P33 -> 250 | AB2: 44712
A3: 44712 | F3: =SUM(B3:E3) -> 0 | G3: =F3 -> 0 | K3: =SUM(F3-H3-J3-I3) -> 0 | L3: =SUM(F3-H3-J3-I3) -> 0 | O3: =SUM(L3-M3-N3+P2) -> 250 | X3: 1 | AE3: =SUM(AC3:AD3) -> 0 | AJ3: 0
A4: 44713 | F4: =SUM(B4:E4) -> 0 | G4: =F4 -> 0 | K4: =SUM(F4-H4-J4-I4) -> 0 | L4: =SUM(F4-H4-J4-I4) -> 0 | O4: =SUM(L4-M4-N4+O3+P4) -> 250 | X4: 2 | AE4: =SUM(AC4:AD4) -> 0 | AJ4: =AE4 -> 0
A5: 44714 | F5: =SUM(B5:E5) -> 0 | G5: =F5 -> 0 | K5: =SUM(F5-H5-J5-I5) -> 0 | L5: =SUM(F5-H5-J5-I5) -> 0 | O5: =SUM(L5-M5-N5+O4+P5) -> 250 | X5: 3 | AE5: =SUM(AC5:AD5) -> 0 | AJ5: 0
A6: 44715 | F6: =SUM(B6:E6) -> 0 | G6: =F6 -> 0 | K6: =SUM(F6-H6-J6-I6) -> 0 | L6: =SUM(F6-H6-J6-I6) -> 0 | O6: =SUM(L6-M6-N6+O5+P6) -> 250 | X6: 4 | AE6: =SUM(AC6:AD6) -> 0 | AJ6: 0
A7: 44716 | F7: =SUM(B7:E7) -> 0 | G7: =F7 -> 0 | K7: =SUM(F7-H7-J7-I7) -> 0 | L7: =SUM(F7-H7-J7-I7) -> 0 | O7: =SUM(L7-M7-N7+O6+P7) -> 250 | X7: 5 | AE7: =SUM(AC7:AD7) -> 0 | AJ7: 0
A8: 44717 | F8: =SUM(B8:E8) -> 0 | G8: =F8 -> 0 | K8: =SUM(F8-H8-J8-I8) -> 0 | L8: =SUM(F8-H8-J8-I8) -> 0 | O8: =SUM(L8-M8-N8+O7+P8) -> 250 | X8: 6 | AE8: =SUM(AC8:AD8) -> 0 | AJ8: 0
A9: 44718 | F9: =SUM(B9:E9) -> 0 | G9: =F9 -> 0 | K9: =SUM(F9-H9-J9-I9) -> 0 | L9: =SUM(F9-H9-J9-I9) -> 0 | O9: =SUM(L9-M9-N9+O8) -> 250 | X9: 7 | AE9: =SUM(AC9:AD9) -> 0 | AJ9: =AE9 -> 0
A10: 44719 | F10: =SUM(B10:E10) -> 0 | G10: =F10 -> 0 | K10: =SUM(F10-H10-J10-I10) -> 0 | L10: =SUM(F10-H10-J10-I10) -> 0 | O10: =SUM(L10-M10-N10+O9) -> 250 | X10: 8 | AE10: =SUM(AC10:AD10) -> 0 | AJ10: =AE10 -> 0
A11: 44720 | F11: =SUM(B11:E11) -> 0 | G11: =F11 -> 0 | K11: =SUM(F11-H11-J11-I11) -> 0 | L11: =SUM(F11-H11-J11-I11) -> 0 | O11: =SUM(L11-M11-N11+O10) -> 250 | X11: 9 | AE11: =SUM(AC11:AD11) -> 0 | AJ11: =AE11 -> 0
A12: 44721 | F12: =SUM(B12:E12) -> 0 | G12: =F12 -> 0 | K12: =SUM(F12-H12-J12-I12) -> 0 | L12: =SUM(F12-H12-J12-I12) -> 0 | O12: =SUM(L12-M12-N12+O11) -> 250 | X12: 10 | AE12: =SUM(AC12:AD12) -> 0 | AJ12: =AE12 -> 0
A13: 44722 | F13: =SUM(B13:E13) -> 0 | G13: =F13 -> 0 | K13: =SUM(F13-H13-J13-I13) -> 0 | L13: =SUM(F13-H13-J13-I13) -> 0 | O13: =SUM(L13-M13-N13+O12) -> 250 | X13: 11 | AE13: =SUM(AC13:AD13) -> 0 | AJ13: =AE13 -> 0
A14: 44723 | F14: =SUM(B14:E14) -> 0 | G14: =F14 -> 0 | K14: =SUM(F14-H14-J14-I14) -> 0 | L14: =SUM(F14-H14-J14-I14) -> 0 | O14: =SUM(L14-M14-N14+O13) -> 250 | X14: 12 | AE14: =SUM(AC14:AD14) -> 0 | AJ14: =AE14 -> 0
A15: 44724 | F15: =SUM(B15:E15) -> 0 | G15: =F15 -> 0 | K15: =SUM(F15-H15-J15-I15) -> 0 | L15: =SUM(F15-H15-J15-I15) -> 0 | O15: =SUM(L15-M15-N15+O14) -> 250 | X15: 13 | AE15: =SUM(AC15:AD15) -> 0 | AJ15: =AE15 -> 0
A16: 44725 | F16: =SUM(B16:E16) -> 0 | G16: =F16 -> 0 | K16: =SUM(F16-H16-J16-I16) -> 0 | L16: =SUM(F16-H16-J16-I16) -> 0 | O16: =SUM(L16-M16-N16+O15) -> 250 | X16: 14 | AE16: =SUM(AC16:AD16) -> 0 | AJ16: =AE16 -> 0
A17: 44726 | F17: =SUM(B17:E17) -> 0 | G17: =F17 -> 0 | K17: =SUM(F17-H17-J17-I17) -> 0 | L17: =SUM(F17-H17-J17-I17) -> 0 | O17: =SUM(L17-M17-N17+O16+P17) -> 250 | X17: 15 | AE17: =SUM(AC17:AD17) -> 0 | AJ17: =AE17 -> 0
A18: 44727 | C18: 878.04 | E18: 36 | F18: =SUM(B18:E18) -> 914.04 | G18: =F18 -> 914.04 | H18: 895.14 | K18: =SUM(F18-H18-J18-I18) -> 18.9 | L18: =SUM(F18-H18-J18-I18) -> 18.9 | O18: =SUM(L18-M18-N18+O17+P18) -> 268.9 | X18: 16 | AE18: =SUM(AC18:AD18) -> 0 | AJ18: =AE18 -> 0
A19: 44728 | F19: =SUM(B19:E19) -> 0 | G19: =F19 -> 0 | K19: =SUM(F19-H19-J19-I19) -> 0 | L19: =SUM(F19-H19-J19-I19) -> 0 | O19: =SUM(L19-M19-N19+O18+P19) -> 268.9 | X19: 17 | AE19: =SUM(AC19:AD19) -> 0 | AJ19: =AE19 -> 0
A20: 44729 | F20: =SUM(B20:E20) -> 0 | G20: =F20 -> 0 | K20: =SUM(F20-H20-J20-I20) -> 0 | L20: =SUM(F20-H20-J20-I20) -> 0 | O20: =SUM(L20-M20-N20+O19+P20) -> 268.9 | X20: 18 | AE20: =SUM(AC20:AD20) -> 0 | AJ20: =AE20 -> 0
A21: 44730 | F21: =SUM(B21:E21) -> 0 | G21: =F21 -> 0 | K21: =SUM(F21-H21-J21-I21) -> 0 | L21: =SUM(F21-H21-J21-I21) -> 0 | O21: =SUM(L21-M21-N21+O20) -> 268.9 | X21: 19 | AE21: =SUM(AC21:AD21) -> 0 | AJ21: =AE21 -> 0
A22: 44731 | F22: =SUM(B22:E22) -> 0 | G22: =F22 -> 0 | K22: =SUM(F22-H22-J22-I22) -> 0 | L22: =SUM(F22-H22-J22-I22) -> 0 | O22: =SUM(L22-M22-N22+O21) -> 268.9 | X22: 20 | AE22: =SUM(AC22:AD22) -> 0 | AJ22: =AE22 -> 0
A23: 44732 | F23: =SUM(B23:E23) -> 0 | G23: =F23 -> 0 | K23: =SUM(F23-H23-J23-I23) -> 0 | L23: =SUM(F23-H23-J23-I23) -> 0 | O23: =SUM(L23-M23-N23+O22) -> 268.9 | X23: 21 | AE23: =SUM(AC23:AD23) -> 0 | AJ23: =AE23 -> 0
A24: 44733 | F24: =SUM(B24:E24) -> 0 | G24: =F24 -> 0 | K24: =SUM(F24-H24-J24-I24) -> 0 | L24: =SUM(F24-H24-J24-I24) -> 0 | O24: =SUM(L24-M24-N24+O23+P24) -> 268.9 | X24: 22 | AE24: =SUM(AC24:AD24) -> 0 | AJ24: =AE24 -> 0
A25: 44734 | F25: =SUM(B25:E25) -> 0 | G25: =F25 -> 0 | K25: =SUM(F25-H25-J25-I25) -> 0 | L25: =SUM(F25-H25-J25-I25) -> 0 | O25: =SUM(L25-M25-N25+O24) -> 268.9 | X25: 26 | AE25: =SUM(AC25:AD25) -> 0 | AJ25: =AE25 -> 0
A26: 44735 | F26: =SUM(B26:E26) -> 0 | G26: =F26 -> 0 | K26: =SUM(F26-H26-J26-I26) -> 0 | L26: =SUM(F26-H26-J26-I26) -> 0 | O26: =SUM(L26-M26-N26+O25) -> 268.9 | X26: 27 | AE26: =SUM(AC26:AD26) -> 0 | AJ26: =AE26 -> 0
A27: 44736 | F27: =SUM(B27:E27) -> 0 | G27: =F27 -> 0 | K27: =SUM(F27-H27-J27-I27) -> 0 | L27: =SUM(F27-H27-J27-I27) -> 0 | O27: =SUM(L27-M27-N27+O26) -> 268.9 | X27: 28 | AE27: =SUM(AC27:AD27) -> 0 | AJ27: =AE27 -> 0
A28: 44737 | F28: =SUM(B28:E28) -> 0 | G28: =F28 -> 0 | K28: =SUM(F28-H28-J28-I28) -> 0 | L28: =SUM(F28-H28-J28-I28) -> 0 | O28: =SUM(L28-M28-N28+O27+P28) -> 268.9 | X28: 29 | AE28: =SUM(AC28:AD28) -> 0 | AJ28: =AE28 -> 0
A29: 44738 | F29: =SUM(B29:E29) -> 0 | G29: =F29 -> 0 | K29: =SUM(F29-H29-J29-I29) -> 0 | L29: =SUM(F29-H29-J29-I29) -> 0 | O29: =SUM(L29-M29-N29+O28) -> 268.9 | X29: 30 | AE29: =SUM(AC29:AD29) -> 0 | AJ29: =AE29 -> 0
A30: 44739 | F30: =SUM(B30:E30) -> 0 | G30: =F30 -> 0 | K30: =SUM(F30-H30-J30-I30) -> 0 | L30: =SUM(F30-H30-J30-I30) -> 0 | O30: =SUM(L30-M30-N30+O29+P30) -> 268.9 | AC30: TVA | AD30: =SUM(AD3:AD29) -> 0
A31: 44740 | F31: =SUM(B31:E31) -> 0 | G31: =F31 -> 0 | K31: =SUM(F31-H31-J31-I31) -> 0 | L31: =SUM(F31-H31-J31-I31) -> 0 | O31: =SUM(L31-M31-N31+O30) -> 268.9 | P31: SOLDE CAISSE
A32: 44741 | F32: =SUM(B32:E32) -> 0 | G32: =F32 -> 0 | K32: =SUM(F32-H32-J32-I32) -> 0 | L32: =SUM(F32-H32-J32-I32) -> 0 | O32: =SUM(L32-M32-N32+O31) -> 268.9 | P32: DU MOIS | AA32: MARGE | AL32: calcul de marge
F33: =SUM(B33:E33) -> 0 | G33: =F33 -> 0 | K33: =SUM(F33-H33-J33-I33) -> 0 | L33: =SUM(F33-H33-J33-I33) -> 0 | O33: =SUM(L33-M33-N33+O32) -> 268.9 | P33: =SUM(O33) -> 268.9 | X33: 1 | Y33: colruyt | Z33: 44726 | AA33: 31042601 7246 | AC33: 40.92 | AD33: 2.46 | AE33: =SUM(AC33:AD33) -> 43.38 | AF33: banotact | AJ33: 0 | AL33: =AC33 -> 40.92 | AM33: 1
B34: =SUM(B5:B33) -> 0 | C34: =SUM(C3:C33) -> 878.04 | D34: =SUM(D3:D33) -> 0 | E34: =SUM(E3:E33) -> 36 | F34: =SUM(F3:F33) -> 914.04 | H34: =SUM(H3:H33) -> 895.14 | J34: =SUM(J3:J33) -> 0 | K34: =SUM(K3:K33) -> 18.9 | L34: =SUM(L3:L33) -> 18.9 | M34: =SUM(M3:M33) -> 0 | N34: =SUM(N3:N33) -> 0 | X34: 2 | Y34: big bag | Z34: 44727 | AA34: 202/6017/33260 | AC34: 450.73 | AD34: 45.96 | AE34: =SUM(AC34:AD34) -> 496.69 | AJ34: =AE34 -> 496.69 | AL34: =AC34 -> 450.73 | AM34: 2
A35: HTVA | B35: =SUM(B3:B33) -> 0 | C35: =SUM(C34/1.06) -> 828.33962 | D35: =SUM(D34/1.12) -> 0 | E35: =SUM(E34/1.21) -> 29.752066 | F35: =SUM(B35:E35) -> 858.09169 | G35: =SUM(G34:G34) -> 0 | L35: TOTAL SORTIE | N35: =SUM(M34:N34) -> 0 | X35: 3 | Y35: bella sicilia | Z35: 44726 | AA35: 222554 | AC35: 518.14 | AD35: 50.29 | AE35: =SUM(AC35:AD35) -> 568.43 | AJ35: =AE35 -> 568.43 | AL35: =AC35 -> 518.14 | AM35: 3
A36: TVA | C36: =SUM(C34-C35) -> 49.700377 | D36: =SUM(D34-D35) -> 0 | E36: =SUM(E34-E35) -> 6.2479339 | F36: =SUM(C36:E36) -> 55.948311 | X36: 4 | Y36: colruyt | Z36: 44728 | AA36: 3104260 17428 | AC36: 168 | AD36: 19.89 | AE36: =SUM(AC36:AD36) -> 187.89 | AF36: banotact | AJ36: 0 | AL36: =AC36 -> 168 | AM36: 4
X37: 5 | AE37: =SUM(AC37:AD37) -> 0 | AJ37: =AE37 -> 0 | AL37: =AC37 -> 0 | AM37: 5
X38: 6 | AE38: =SUM(AC38:AD38) -> 0 | AJ38: 0 | AL38: =AC38 -> 0 | AM38: 6
X39: 7 | AE39: =SUM(AC39:AD39) -> 0 | AJ39: =AE39 -> 0 | AL39: =AC39 -> 0 | AM39: 7
X40: 8 | AE40: =SUM(AC40:AD40) -> 0 | AJ40: =AE40 -> 0 | AL40: =AC40 -> 0 | AM40: 8
...

Sheet MAI 2026
A1: 44681 | C1: RECETTE | G1: CAISSE | M1: MOUVEMENT CAISSE | P1: CAISSE MOIS PREC | Q1: PAYEMENT FOURNISSEUR CAISSE | R1: MONTANT | S1: TOTAL | T1: DATE SORTIE | Y1: FOURNISSEUR | Z1: DATE | AA1: REFERENCE | AB1: COMPTE | AC1: HTVA | AD1: TVA | AE1: MONTANT | AF1: PAIEMENT | AG1: CAISSE | AH1: DATE | AI1: ECHEANCE
A2: DATE | B2: FACTURE | C2: 6 | D2: 12 | E2: 21 | F2: TOTAL | G2: CHIFF | H2: carte | I2: cadeau0 | J2: bque | K2: liquide | L2: TOT CAIS | M2: SORTIE | N2: vers ban | O2: solde cai | P2: ='AVRIL 2026'!P33 -> 250 | AB2: 44681
A3: 44681 | F3: =SUM(B3:E3) -> 0 | G3: =F3 -> 0 | K3: =SUM(F3-H3-J3-I3) -> 0 | L3: =SUM(F3-H3-J3-I3) -> 0 | O3: =SUM(L3-M3-N3+P2) -> 250 | X3: 1 | AE3: =SUM(AC3:AD3) -> 0 | AJ3: 0
A4: 44682 | F4: =SUM(B4:E4) -> 0 | G4: =F4 -> 0 | K4: =SUM(F4-H4-J4-I4) -> 0 | L4: =SUM(F4-H4-J4-I4) -> 0 | O4: =SUM(L4-M4-N4+O3+P4) -> 250 | X4: 2 | AE4: =SUM(AC4:AD4) -> 0 | AJ4: =AE4 -> 0
A5: 44683 | F5: =SUM(B5:E5) -> 0 | G5: =F5 -> 0 | K5: =SUM(F5-H5-J5-I5) -> 0 | L5: =SUM(F5-H5-J5-I5) -> 0 | O5: =SUM(L5-M5-N5+O4+P5) -> 250 | X5: 3 | AE5: =SUM(AC5:AD5) -> 0 | AJ5: 0
A6: 44684 | F6: =SUM(B6:E6) -> 0 | G6: =F6 -> 0 | K6: =SUM(F6-H6-J6-I6) -> 0 | L6: =SUM(F6-H6-J6-I6) -> 0 | O6: =SUM(L6-M6-N6+O5+P6) -> 250 | X6: 4 | AE6: =SUM(AC6:AD6) -> 0 | AJ6: 0
A7: 44685 | F7: =SUM(B7:E7) -> 0 | G7: =F7 -> 0 | K7: =SUM(F7-H7-J7-I7) -> 0 | L7: =SUM(F7-H7-J7-I7) -> 0 | O7: =SUM(L7-M7-N7+O6+P7) -> 250 | X7: 5 | AE7: =SUM(AC7:AD7) -> 0 | AJ7: 0
